Workbook

Sheet DASHBOARD
B2: TWENTY SWIM - DASHBOARD KOLAM MITRA
B3: Semua angka dihitung otomatis dari tab Kolam Mitra - dashboard ikut berubah saat data diperbarui.
B5: TOTAL KOLAM | E5: AKTIF | H5: STOP | K5: ADA KELUHAN | N5: RISIKO TINGGI | Q5: BELUM DILENGKAPI
B6: =COUNTA('Kolam Mitra'!$B$5:$B$404) | E6: ='Data Dashboard'!T4 | H6: ='Data Dashboard'!T5 | K6: ='Data Dashboard'!T10 | N6: ='Data Dashboard'!H6 | Q6: ='Data Dashboard'!E9
B8: kolam mitra terdaftar | E8: status kerjasama berjalan | H8: kerjasama berhenti | K8: kolam dengan catatan keluhan | N8: kerjasama rapuh / perlu cadangan | Q8: status kerjasama masih kosong
B10: SEBARAN & KERJASAMA
B27: RISIKO & BIAYA
B44: FASILITAS & PERJANJIAN
B61: RINGKASAN PER WILAYAH
B62: Wilayah | E62: Kolam | H62: Aktif | K62: Stop | N62: Ada Keluhan | Q62: Risiko Tinggi
B63: ='Data Dashboard'!A17 | E63: ='Data Dashboard'!B17 | H63: ='Data Dashboard'!C17 | K63: ='Data Dashboard'!D17 | N63: ='Data Dashboard'!E17 | Q63: ='Data Dashboard'!F17
B64: ='Data Dashboard'!A18 | E64: ='Data Dashboard'!B18 | H64: ='Data Dashboard'!C18 | K64: ='Data Dashboard'!D18 | N64: ='Data Dashboard'!E18 | Q64: ='Data Dashboard'!F18
B65: ='Data Dashboard'!A19 | E65: ='Data Dashboard'!B19 | H65: ='Data Dashboard'!C19 | K65: ='Data Dashboard'!D19 | N65: ='Data Dashboard'!E19 | Q65: ='Data Dashboard'!F19
B66: ='Data Dashboard'!A20 | E66: ='Data Dashboard'!B20 | H66: ='Data Dashboard'!C20 | K66: ='Data Dashboard'!D20 | N66: ='Data Dashboard'!E20 | Q66: ='Data Dashboard'!F20
B67: ='Data Dashboard'!A21 | E67: ='Data Dashboard'!B21 | H67: ='Data Dashboard'!C21 | K67: ='Data Dashboard'!D21 | N67: ='Data Dashboard'!E21 | Q67: ='Data Dashboard'!F21
B68: ='Data Dashboard'!A22 | E68: ='Data Dashboard'!B22 | H68: ='Data Dashboard'!C22 | K68: ='Data Dashboard'!D22 | N68: ='Data Dashboard'!E22 | Q68: ='Data Dashboard'!F22
B69: ='Data Dashboard'!A23 | E69: ='Data Dashboard'!B23 | H69: ='Data Dashboard'!C23 | K69: ='Data Dashboard'!D23 | N69: ='Data Dashboard'!E23 | Q69: ='Data Dashboard'!F23
B70: ='Data Dashboard'!A24 | E70: ='Data Dashboard'!B24 | H70: ='Data Dashboard'!C24 | K70: ='Data Dashboard'!D24 | N70: ='Data Dashboard'!E24 | Q70: ='Data Dashboard'!F24
B72: Privasi: dashboard hanya menampilkan angka agregat - tanpa nama kolam, alamat, atau kontak PIC.
B73: Catatan: 'Ada Keluhan' menghitung baris yang kolom Catatan Keluhan-nya terisi; Fasilitas dihitung dari kata kunci 'Air Hangat' dan 'Makan/Minum'.

Sheet Kolam Mitra
A1: TWENTY SWIM - BUKU KOLAM MITRA
A2: Data kolam + info internal kerjasama. Sel kuning = ada catatan keluhan. Sel abu-abu muda = kolom yang masih perlu dilengkapi. Kolom dropdown tinggal pilih. | M2: Terisi: | N2: =COUNTA($B$5:$B$404) | O2: kolam
A4: No | B4: Nama Kolam | C4: Wilayah | D4: Alamat | E4: Harga Tiket | F4: Fasilitas | G4: Status Kerjasama | H4: Biaya Kerjasama | I4: Bentuk Perjanjian | J4: Biaya Coach | K4: Biaya Pendamping | L4: PIC Kolam (nama & kontak) | M4: Tingkat Risiko | N4: Catatan Keluhan | O4: Status Aktif
A5: =IF($B5<>"",ROW()-4,"") | B5: Garden Hotel Cipaku | C5: Bandung Utara | D5: Jl. Cipaku Indah X No.2-4, Ledeng, Cidadap | E5: WD 50.000 / WE 55.000 | J5: Coach kena biaya | K5: Gratis | O5: Aktif
A6: =IF($B6<>"",ROW()-4,"") | B6: Hotel Neo Dipatiukur | C6: Bandung Kota | D6: Jl. Dipatiukur, Coblong | E6: 80.000 | F6: Makan/Minum | J6: Gratis | K6: Gratis | O6: Aktif
A7: =IF($B7<>"",ROW()-4,"") | B7: Hotel Kytos Setiabudhi | C7: Bandung Utara | D7: Jl. Dr. Setiabudhi, Gegerkalong, Sukasari | E7: 75.000 | F7: Air Hangat | J7: Gratis | K7: Gratis | N7: Ortu: harga tiket dirasa mahal | O7: Aktif
A8: =IF($B8<>"",ROW()-4,"") | B8: Point C Hotel | C8: Bandung Utara | D8: Komplek The Setiabudhi Terrace, Jl. Cipaku Indah II No.21 | E8: 75.000 | F8: Air Hangat, Makan/Minum | J8: Gratis | K8: Gratis | O8: Aktif
A9: =IF($B9<>"",ROW()-4,"") | B9: Calma Kitchen and Pool | C9: Bandung Barat | D9: Jl. Cipedes Center, Sukajadi | E9: 70.000 | F9: Makan/Minum | J9: Gratis | K9: Gratis | O9: Aktif
A10: =IF($B10<>"",ROW()-4,"") | B10: BSD Bandung (Riung Mekar) | C10: Bandung Timur | D10: Riung Bandung | E10: 30.000 | J10: Coach kena biaya | K10: Gratis | N10: Ortu: kadang kolam kotor | O10: Aktif
A11: =IF($B11<>"",ROW()-4,"") | B11: Hotel Oakwood Bandung | C11: Bandung Kota | D11: Jl. Merdeka (area Sumur Bandung) | E11: 50.000 | F11: Makan/Minum | J11: Gratis | K11: Gratis | O11: Aktif
A12: =IF($B12<>"",ROW()-4,"") | B12: Hotel Savoy Homann | C12: Bandung Kota | D12: Jl. Asia Afrika No.112, Cikawao, Lengkong | E12: 50.000 | F12: Air Hangat | J12: Gratis | K12: Gratis | O12: Aktif
A13: =IF($B13<>"",ROW()-4,"") | B13: Grand Arjuna Hotel Bandung | C13: Bandung Utara | D13: Jl. Ciumbuleuit No.152, Cidadap | E13: 50.000 | J13: Gratis | K13: Gratis | O13: Aktif
A14: =IF($B14<>"",ROW()-4,"") | B14: Sampoerna Sport Club | C14: Bandung Utara | D14: Jl. Setiabudhi No.10, Isola, Sukasari | E14: WD 47.000 / WE 52.000 | F14: Air Hangat | J14: Gratis | K14: Gratis | O14: Aktif
A15: =IF($B15<>"",ROW()-4,"") | B15: Sari Ater Kamboti Bandung | C15: Bandung Barat | D15: Jl. Lemahneundeut No.7, Sukawarna, Sukajadi | E15: 20.000 | J15: Coach kena biaya | K15: Gratis | O15: Aktif
A16: =IF($B16<>"",ROW()-4,"") | B16: Cozy Catellya Hotel | C16: Bandung Utara | D16: Jl. Cipaku Indah III No.11, Ledeng, Cidadap | E16: 35.000 | J16: Gratis | K16: Gratis | O16: Aktif
A17: =IF($B17<>"",ROW()-4,"") | B17: Pandiga Sport Club | C17: Cimahi | D17: Jl. Sirnarasa No.11, Cihanjuang, Cimahi Utara | E17: WD 35.000 / WE 40.000 | J17: Gratis | K17: Gratis | O17: Aktif
A18: =IF($B18<>"",ROW()-4,"") | B18: Buah Batu Regency | C18: Bandung Selatan | D18: Komplek Buah Batu Regency, Jl. Terusan Buah Batu No.7A, Kujangsari | E18: 30.000 | J18: Gratis | K18: Gratis | O18: Aktif
A19: =IF($B19<>"",ROW()-4,"") | B19: Grand Pacific Hotel | C19: Bandung Kota | D19: Jl. HOS Tjokroaminoto No.100, Pasir Kaliki | E19: 25.000 | J19: Gratis | K19: Gratis | O19: Aktif
A20: =IF($B20<>"",ROW()-4,"") | B20: Kolam Renang WIKA Bandung | C20: Bandung Timur | D20: Jl. Jaya Wijaya No.1, Sindang Jaya, Mandalajati | E20: WD 25.000 / WE 35.000 | J20: Gratis | K20: Kena biaya | N20: Ortu: kolam sering penuh | O20: Aktif
A21: =IF($B21<>"",ROW()-4,"") | B21: Villa Salse (Dago Giri) | C21: Bandung Utara | D21: Jl. Dago Giri No.101 | E21: WD 25.000 / WE 35.000 | J21: Gratis | K21: Gratis | O21: Aktif
A22: =IF($B22<>"",ROW()-4,"") | B22: Kolam Renang Tongkeng | C22: Bandung Kota | D22: Jl. Tongkeng, Kawasan Lengkong | E22: 25.000 | J22: Gratis | K22: Kena biaya | O22: Aktif
A23: =IF($B23<>"",ROW()-4,"") | B23: Kolam Renang Saraga ITB | C23: Bandung Kota | D23: Jl. Tamansari No.73, Lb. Siliwangi, Coblong | E23: WD 25.000 / WE 30.000 | J23: Coach kena biaya | K23: Kena biaya | O23: Aktif
A24: =IF($B24<>"",ROW()-4,"") | B24: Kolam Renang Rumah Oma Opa | C24: Bandung Timur | D24: Girimekar, Cilengkrang, Kab. Bandung | E24: 20.000 | J24: Gratis | K24: Kena biaya | O24: Aktif
A25: =IF($B25<>"",ROW()-4,"") | B25: Kolam Renang Tirta Mulya | C25: Bandung Timur | D25: Jl. A.H. Nasution No.228, Cipadung Kulon, Panyileukan | E25: 20.000 | J25: Gratis | K25: Gratis | O25: Aktif
A26: =IF($B26<>"",ROW()-4,"") | B26: Kolam Renang UPI | C26: Bandung Utara | D26: Jl. Dr. Setiabudhi No.229 | E26: 20.000 | J26: Gratis | K26: Gratis | O26: Aktif
A27: =IF($B27<>"",ROW()-4,"") | B27: Cherryfield Club House | C27: Bandung Selatan | D27: Jl. Cigantiri, Desa Cipagalo, Bojongsoang | E27: 35.000 | J27: Gratis | K27: Kena biaya | O27: Aktif
A28: =IF($B28<>"",ROW()-4,"") | B28: Hotel Laska | C28: Kota Sukabumi | D28: Jl. Bhayangkara No.28, Sriwidari | E28: 50.000 | F28: Makan/Minum | J28: Gratis | K28: Gratis | O28: Aktif
A29: =IF($B29<>"",ROW()-4,"") | B29: Grand Permata Hijau (Air Hangat) | C29: Kota Sukabumi | D29: Jl. Bhayangkara No.46, Gunungpuyuh | E29: 25.000 anak / 50.000 dewasa | F29: Air Hangat | J29: Gratis | K29: Gratis | O29: Aktif
A30: =IF($B30<>"",ROW()-4,"") | B30: Wisata Alam Oasis | C30: Kota Sukabumi | D30: Jl. Mayor Mahmud, Sukajaya | E30: 15.000 | J30: Gratis | K30: Gratis | O30: Aktif
A31: =IF($B31<>"",ROW()-4,"") | B31: Prana Swimming Pool | C31: Kota Sukabumi | D31: Jl. Perana, Cikole | E31: WD 10.000 / WE 15.000 | J31: Gratis | K31: Gratis | O31: Aktif
A32: =IF($B32<>"",ROW()-4,"") | B32: Fresh Hotel | C32: Kota Sukabumi | D32: Jl. Bhayangkara No.127 | E32: 50.000 anak / 75.000 dewasa | F32: Makan/Minum | J32: Gratis | K32: Gratis | O32: Aktif
A33: =IF($B33<>"",ROW()-4,"") | B33: Pesona Pangrango | C33: Kab. Sukabumi | D33: Jl. Parungseah | E33: 20.000 | J33: Gratis | K33: Kena biaya | O33: Aktif
A34: =IF($B34<>"",ROW()-4,"") | B34: Pesona Cibeureum | C34: Kab. Sukabumi | D34: Sukaraja | E34: 10.000 | J34: Gratis | K34: Gratis | O34: Aktif
A35: =IF($B35<>"",ROW()-4,"") | B35: Permata Waterpark | C35: Kab. Sukabumi | D35: Jl. Jalur, Cibatu, Cisaat | E35: WD 15.000 / WE 20.000 | J35: Gratis | K35: Kena biaya | O35: Aktif
A36: =IF($B36<>"",ROW()-4,"") | B36: Detani Water Park | C36: Kab. Sukabumi | D36: Goalpara | E36: WD 20.000 / WE 25.000 | J36: Gratis | K36: Kena biaya | O36: Aktif
A37: =IF($B37<>"",ROW()-4,"") | B37: Sindang Asri | C37: Kab. Sukabumi | D37: Babakan Jaya, Parungkuda | E37: 20.000 | J37: Gratis | K37: Gratis | O37: Aktif
A38: =IF($B38<>"",ROW()-4,"") | B38: YSR Himalaya Resort | C38: Kab. Sukabumi | D38: Jl. Panyingkiran, Pawenang, Nagrak | E38: 25.000 | J38: Gratis | K38: Gratis | O38: Aktif
A39: =IF($B39<>"",ROW()-4,"") | B39: Ali Swimming Pool | C39: Kab. Sukabumi | D39: Jl. Raya Cikukulu, Cisande | E39: WD 20.000 / WE 25.000 | J39: Gratis | K39: Kena biaya | O39: Aktif
A40: =IF($B40<>"",ROW()-4,"")
A41: =IF($B41<>"",ROW()-4,"")
...

Sheet Panduan
A1: BUKU KOLAM MITRA - PANDUAN
A3: KOLOM YANG PERLU DILENGKAPI (sel abu-abu muda di tab Kolam Mitra)
A4: Status Kerjasama | B4: Pilih: Gratis (murid bayar tiket) / Member bulanan / Bagi hasil / Coach kena biaya / Lainnya.
A5: Biaya Kerjasama | B5: Isi nominal. Contoh: 'Rp2.000.000/bln' (member) atau '20%' (bagi hasil). Kosongkan kalau gratis.
A6: Bentuk Perjanjian | B6: Lisan atau Tertulis.
A7: PIC Kolam | B7: Nama & nomor kontak orang yang diurus di kolam itu.
A8: Tingkat Risiko | B8: Tinggi untuk kolam hotel yang manajemennya sering ganti / kerjasama rapuh.
A10: YANG SUDAH TERISI
A11: Nama, Wilayah, Alamat, Harga Tiket, Fasilitas | B11: Dari website lokasi.
A12: Biaya Coach & Pendamping | B12: Dari catatan website.
A13: Catatan Keluhan | B13: Dari evaluasi ortu. Sel otomatis kuning bila ada catatan.
A15: ARTI WARNA
A16: Kuning (Catatan Keluhan) | B16: Ada catatan keluhan dari ortu.
A17: Abu-abu muda | B17: Kolom masih kosong dan perlu dilengkapi.
A18: Hijau / Kuning / Merah (Risiko) | B18: Rendah / Sedang / Tinggi.
A19: Hijau / Merah (Status Aktif) | B19: Aktif / Stop. Nama kolam Stop dicoret.
A21: GUNA BUKU INI
A22: Beban biaya | B22: Lihat kolam mana yang membebani: bandingkan Biaya Kerjasama dengan seberapa sering dipakai.
A23: Deteksi risiko | B23: Kalau 1 kolam Risiko Tinggi tutup, berapa member/sesi yang goyah? Lihat kartu Risiko Tinggi di DASHBOARD.
A24: Tampung keluhan | B24: Keluhan kolam dari evaluasi jadi dasar pindah/diversifikasi kolam.
A26: CARA PAKAI
A27: Tab Kolam Mitra | B27: Satu-satunya tab yang diisi. Tambah kolam baru di baris kosong; nomor urut otomatis.
A28: Tab DASHBOARD | B28: Kartu angka, grafik, dan ringkasan per wilayah menghitung sendiri dari tab Kolam Mitra.
A29: Tab Daftar & Data Dashboard | B29: Disembunyikan: sumber dropdown dan angka grafik. Jangan diubah.

Sheet Data Dashboard
A1: SUMBER DATA DASHBOARD - otomatis dari tab Kolam Mitra, jangan diubah manual
A3: Wilayah | B3: Kolam | D3: Status Kerjasama | E3: Kolam | G3: Tingkat Risiko | H3: Kolam | J3: Bentuk Perjanjian | K3: Kolam | M3: Biaya Coach & Pendamping | N3: Kolam | P3: Fasilitas | Q3: Kolam | S3: Status Aktif | T3: Kolam
A4: Bandung Kota | B4: =COUNTIF('Kolam Mitra'!$C$5:$C$404,$A4) | D4: Gratis (murid bayar tiket) | E4: =COUNTIF('Kolam Mitra'!$G$5:$G$404,$D4) | G4: Rendah | H4: =COUNTIF('Kolam Mitra'!$M$5:$M$404,$G4) | J4: Lisan | K4: =COUNTIF('Kolam Mitra'!$I$5:$I$404,$J4) | M4: Coach: Gratis | N4: =COUNTIF('Kolam Mitra'!$J$5:$J$404,"Gratis") | P4: Air Hangat | Q4: =COUNTIF('Kolam Mitra'!$F$5:$F$404,"*Air Hangat*") | S4: Aktif | T4: =COUNTIF('Kolam Mitra'!$O$5:$O$404,$S4)
A5: Bandung Utara | B5: =COUNTIF('Kolam Mitra'!$C$5:$C$404,$A5) | D5: Member bulanan | E5: =COUNTIF('Kolam Mitra'!$G$5:$G$404,$D5) | G5: Sedang | H5: =COUNTIF('Kolam Mitra'!$M$5:$M$404,$G5) | J5: Tertulis | K5: =COUNTIF('Kolam Mitra'!$I$5:$I$404,$J5) | M5: Coach: Kena biaya | N5: =COUNTIF('Kolam Mitra'!$J$5:$J$404,"Coach kena biaya") | P5: Makan/Minum | Q5: =COUNTIF('Kolam Mitra'!$F$5:$F$404,"*Makan/Minum*") | S5: Stop | T5: =COUNTIF('Kolam Mitra'!$O$5:$O$404,$S5)
A6: Bandung Selatan | B6: =COUNTIF('Kolam Mitra'!$C$5:$C$404,$A6) | D6: Bagi hasil | E6: =COUNTIF('Kolam Mitra'!$G$5:$G$404,$D6) | G6: Tinggi | H6: =COUNTIF('Kolam Mitra'!$M$5:$M$404,$G6) | J6: (Belum diisi) | K6: =COUNTA('Kolam Mitra'!$B$5:$B$404)-SUM(K4:K5) | M6: Pendamping: Gratis | N6: =COUNTIF('Kolam Mitra'!$K$5:$K$404,"Gratis") | P6: (Tanpa catatan) | Q6: =COUNTA('Kolam Mitra'!$B$5:$B$404)-COUNTA('Kolam Mitra'!$F$5:$F$404) | S6: (Belum diisi) | T6: =COUNTA('Kolam Mitra'!$B$5:$B$404)-SUM(T4:T5)
A7: Bandung Timur | B7: =COUNTIF('Kolam Mitra'!$C$5:$C$404,$A7) | D7: Coach kena biaya | E7: =COUNTIF('Kolam Mitra'!$G$5:$G$404,$D7) | G7: (Belum diisi) | H7: =COUNTA('Kolam Mitra'!$B$5:$B$404)-SUM(H4:H6) | M7: Pendamping: Kena biaya | N7: =COUNTIF('Kolam Mitra'!$K$5:$K$404,"Kena biaya")
A8: Bandung Barat | B8: =COUNTIF('Kolam Mitra'!$C$5:$C$404,$A8) | D8: Lainnya | E8: =COUNTIF('Kolam Mitra'!$G$5:$G$404,$D8)
A9: Cimahi | B9: =COUNTIF('Kolam Mitra'!$C$5:$C$404,$A9) | D9: (Belum diisi) | E9: =COUNTA('Kolam Mitra'!$B$5:$B$404)-SUM(E4:E8) | S9: Keluhan | T9: Kolam
A10: Kota Sukabumi | B10: =COUNTIF('Kolam Mitra'!$C$5:$C$404,$A10) | S10: Ada catatan keluhan | T10: =COUNTA('Kolam Mitra'!$N$5:$N$404)
A11: Kab. Sukabumi | B11: =COUNTIF('Kolam Mitra'!$C$5:$C$404,$A11) | S11: Tanpa keluhan | T11: =COUNTA('Kolam Mitra'!$B$5:$B$404)-COUNTA('Kolam Mitra'!$N$5:$N$404)
A12: (Belum diisi) | B12: =COUNTA('Kolam Mitra'!$B$5:$B$404)-SUM(B4:B11)
S14: Total kolam | T14: =COUNTA('Kolam Mitra'!$B$5:$B$404)
A16: Wilayah | B16: Kolam | C16: Aktif | D16: Stop | E16: Ada Keluhan | F16: Risiko Tinggi | G16: Coach Gratis
A17: Bandung Kota | B17: =COUNTIF('Kolam Mitra'!$C$5:$C$404,$A17) | C17: =COUNTIFS('Kolam Mitra'!$C$5:$C$404,$A17,'Kolam Mitra'!$O$5:$O$404,"Aktif") | D17: =COUNTIFS('Kolam Mitra'!$C$5:$C$404,$A17,'Kolam Mitra'!$O$5:$O$404,"Stop") | E17: =COUNTIFS('Kolam Mitra'!$C$5:$C$404,$A17,'Kolam Mitra'!$N$5:$N$404,"?*") | F17: =COUNTIFS('Kolam Mitra'!$C$5:$C$404,$A17,'Kolam Mitra'!$M$5:$M$404,"Tinggi") | G17: =COUNTIFS('Kolam Mitra'!$C$5:$C$404,$A17,'Kolam Mitra'!$J$5:$J$404,"Gratis")
A18: Bandung Utara | B18: =COUNTIF('Kolam Mitra'!$C$5:$C$404,$A18) | C18: =COUNTIFS('Kolam Mitra'!$C$5:$C$404,$A18,'Kolam Mitra'!$O$5:$O$404,"Aktif") | D18: =COUNTIFS('Kolam Mitra'!$C$5:$C$404,$A18,'Kolam Mitra'!$O$5:$O$404,"Stop") | E18: =COUNTIFS('Kolam Mitra'!$C$5:$C$404,$A18,'Kolam Mitra'!$N$5:$N$404,"?*") | F18: =COUNTIFS('Kolam Mitra'!$C$5:$C$404,$A18,'Kolam Mitra'!$M$5:$M$404,"Tinggi") | G18: =COUNTIFS('Kolam Mitra'!$C$5:$C$404,$A18,'Kolam Mitra'!$J$5:$J$404,"Gratis")
A19: Bandung Selatan | B19: =COUNTIF('Kolam Mitra'!$C$5:$C$404,$A19) | C19: =COUNTIFS('Kolam Mitra'!$C$5:$C$404,$A19,'Kolam Mitra'!$O$5:$O$404,"Aktif") | D19: =COUNTIFS('Kolam Mitra'!$C$5:$C$404,$A19,'Kolam Mitra'!$O$5:$O$404,"Stop") | E19: =COUNTIFS('Kolam Mitra'!$C$5:$C$404,$A19,'Kolam Mitra'!$N$5:$N$404,"?*") | F19: =COUNTIFS('Kolam Mitra'!$C$5:$C$404,$A19,'Kolam Mitra'!$M$5:$M$404,"Tinggi") | G19: =COUNTIFS('Kolam Mitra'!$C$5:$C$404,$A19,'Kolam Mitra'!$J$5:$J$404,"Gratis")
A20: Bandung Timur | B20: =COUNTIF('Kolam Mitra'!$C$5:$C$404,$A20) | C20: =COUNTIFS('Kolam Mitra'!$C$5:$C$404,$A20,'Kolam Mitra'!$O$5:$O$404,"Aktif") | D20: =COUNTIFS('Kolam Mitra'!$C$5:$C$404,$A20,'Kolam Mitra'!$O$5:$O$404,"Stop") | E20: =COUNTIFS('Kolam Mitra'!$C$5:$C$404,$A20,'Kolam Mitra'!$N$5:$N$404,"?*") | F20: =COUNTIFS('Kolam Mitra'!$C$5:$C$404,$A20,'Kolam Mitra'!$M$5:$M$404,"Tinggi") | G20: =COUNTIFS('Kolam Mitra'!$C$5:$C$404,$A20,'Kolam Mitra'!$J$5:$J$404,"Gratis")
A21: Bandung Barat | B21: =COUNTIF('Kolam Mitra'!$C$5:$C$404,$A21) | C21: =COUNTIFS('Kolam Mitra'!$C$5:$C$404,$A21,'Kolam Mitra'!$O$5:$O$404,"Aktif") | D21: =COUNTIFS('Kolam Mitra'!$C$5:$C$404,$A21,'Kolam Mitra'!$O$5:$O$404,"Stop") | E21: =COUNTIFS('Kolam Mitra'!$C$5:$C$404,$A21,'Kolam Mitra'!$N$5:$N$404,"?*") | F21: =COUNTIFS('Kolam Mitra'!$C$5:$C$404,$A21,'Kolam Mitra'!$M$5:$M$404,"Tinggi") | G21: =COUNTIFS('Kolam Mitra'!$C$5:$C$404,$A21,'Kolam Mitra'!$J$5:$J$404,"Gratis")
A22: Cimahi | B22: =COUNTIF('Kolam Mitra'!$C$5:$C$404,$A22) | C22: =COUNTIFS('Kolam Mitra'!$C$5:$C$404,$A22,'Kolam Mitra'!$O$5:$O$404,"Aktif") | D22: =COUNTIFS('Kolam Mitra'!$C$5:$C$404,$A22,'Kolam Mitra'!$O$5:$O$404,"Stop") | E22: =COUNTIFS('Kolam Mitra'!$C$5:$C$404,$A22,'Kolam Mitra'!$N$5:$N$404,"?*") | F22: =COUNTIFS('Kolam Mitra'!$C$5:$C$404,$A22,'Kolam Mitra'!$M$5:$M$404,"Tinggi") | G22: =COUNTIFS('Kolam Mitra'!$C$5:$C$404,$A22,'Kolam Mitra'!$J$5:$J$404,"Gratis")
A23: Kota Sukabumi | B23: =COUNTIF('Kolam Mitra'!$C$5:$C$404,$A23) | C23: =COUNTIFS('Kolam Mitra'!$C$5:$C$404,$A23,'Kolam Mitra'!$O$5:$O$404,"Aktif") | D23: =COUNTIFS('Kolam Mitra'!$C$5:$C$404,$A23,'Kolam Mitra'!$O$5:$O$404,"Stop") | E23: =COUNTIFS('Kolam Mitra'!$C$5:$C$404,$A23,'Kolam Mitra'!$N$5:$N$404,"?*") | F23: =COUNTIFS('Kolam Mitra'!$C$5:$C$404,$A23,'Kolam Mitra'!$M$5:$M$404,"Tinggi") | G23: =COUNTIFS('Kolam Mitra'!$C$5:$C$404,$A23,'Kolam Mitra'!$J$5:$J$404,"Gratis")
A24: Kab. Sukabumi | B24: =COUNTIF('Kolam Mitra'!$C$5:$C$404,$A24) | C24: =COUNTIFS('Kolam Mitra'!$C$5:$C$404,$A24,'Kolam Mitra'!$O$5:$O$404,"Aktif") | D24: =COUNTIFS('Kolam Mitra'!$C$5:$C$404,$A24,'Kolam Mitra'!$O$5:$O$404,"Stop") | E24: =COUNTIFS('Kolam Mitra'!$C$5:$C$404,$A24,'Kolam Mitra'!$N$5:$N$404,"?*") | F24: =COUNTIFS('Kolam Mitra'!$C$5:$C$404,$A24,'Kolam Mitra'!$M$5:$M$404,"Tinggi") | G24: =COUNTIFS('Kolam Mitra'!$C$5:$C$404,$A24,'Kolam Mitra'!$J$5:$J$404,"Gratis")

Sheet Daftar
A1: Wilayah | C1: Status Kerjasama | E1: Bentuk Perjanjian | G1: Biaya Coach | I1: Biaya Pendamping | K1: Tingkat Risiko | M1: Status Aktif
A2: Bandung Kota | C2: Gratis (murid bayar tiket) | E2: Lisan | G2: Gratis | I2: Gratis | K2: Rendah | M2: Aktif
A3: Bandung Utara | C3: Member bulanan | E3: Tertulis | G3: Coach kena biaya | I3: Kena biaya | K3: Sedang | M3: Stop
A4: Bandung Selatan | C4: Bagi hasil | K4: Tinggi
A5: Bandung Timur | C5: Coach kena biaya
A6: Bandung Barat | C6: Lainnya
A7: Cimahi
A8: Kota Sukabumi
A9: Kab. Sukabumi
