Workbook

Sheet DASHBOARD
B2: TWENTY SWIM - DASHBOARD LEVEL & JADWAL COACH (BANDUNG)
B3: Semua angka dihitung otomatis dari 30 tab coach - tambah/ubah siswa di tab coach, dashboard ikut berubah.
B5: TOTAL SISWA | F5: JUMLAH COACH | J5: SOSIALISASI SUDAH | N5: SOSIALISASI BELUM
B6: =COUNTA('Aina Triyana Anggraini'!$B$5:$B$54)+COUNTA('Aldi Suryadinata'!$B$5:$B$54)+COUNTA('Asyahlan Hielmy'!$B$5:$B$54)+COUNTA('Asyira Nur Haida'!$B$5:$B$54)+COUNTA('Bayu Rizki Alfarizi'!$B$5:$B$54)+COUNTA('Chandanie Nely Agustin'!$B$5:$B$54)+COUNTA('Dida Zein Risty'!$B$5:$B$54)+COUNTA('Fadil Rijatul Haq'!$B$5:$B$54)+COUNTA('Faega Fitriani Dwi Putri'!$B$5:$B$54)+COUNTA('Fajri Rizki Robbani'!$B$5:$B$54)+COUNTA('Fakhri Safrudin Sopandi'!$B$5:$B$54)+COUNTA('Moh. Rizky Nugraha'!$B$5:$B$54)+COUNTA('Muhammad Akbar Putra'!$B$5:$B$54)+COUNTA('Muhammad Hafidz Ramadhan'!$B$5:$B$54)+COUNTA('Muhammad Lutfhi Mubarrok'!$B$5:$B$54)+COUNTA('Muhammad Nadhira Shafar'!$B$5:$B$54)+COUNTA('Muhammad Rafi Fakhrul Aiman'!$B$5:$B$54)+COUNTA('Muhammad Reyvin Aryaguna'!$B$5:$B$54)+COUNTA('Nadzar Akbar Subagja'!$B$5:$B$54)+COUNTA('Najwan Muhammad Ghalib'!$B$5:$B$54)+COUNTA('Nia Rizkiyanti'!$B$5:$B$54)+COUNTA('Nur Ainillah Nabawi'!$B$5:$B$54)+COUNTA('Nurul Khairunnissa'!$B$5:$B$54)+COUNTA('Putri Maharani'!$B$5:$B$54)+COUNTA('Rika Kartika'!$B$5:$B$54)+COUNTA('Riva Nur Fathiya Safitri'!$B$5:$B$54)+COUNTA('Shintia Nur Fadillah'!$B$5:$B$54)+COUNTA('Sinta Faoziah'!$B$5:$B$54)+COUNTA('Tiara Anastasya Gumilar'!$B$5:$B$54)+COUNTA('Tiara Maelani'!$B$5:$B$54) | F6: =COUNTA(Daftar!$I$2:$I$31) | J6: =COUNTIF('Aina Triyana Anggraini'!$G$5:$G$54,"Sudah")+COUNTIF('Aldi Suryadinata'!$G$5:$G$54,"Sudah")+COUNTIF('Asyahlan Hielmy'!$G$5:$G$54,"Sudah")+COUNTIF('Asyira Nur Haida'!$G$5:$G$54,"Sudah")+COUNTIF('Bayu Rizki Alfarizi'!$G$5:$G$54,"Sudah")+COUNTIF('Chandanie Nely Agustin'!$G$5:$G$54,"Sudah")+COUNTIF('Dida Zein Risty'!$G$5:$G$54,"Sudah")+COUNTIF('Fadil Rijatul Haq'!$G$5:$G$54,"Sudah")+COUNTIF('Faega Fitriani Dwi Putri'!$G$5:$G$54,"Sudah")+COUNTIF('Fajri Rizki Robbani'!$G$5:$G$54,"Sudah")+COUNTIF('Fakhri Safrudin Sopandi'!$G$5:$G$54,"Sudah")+COUNTIF('Moh. Rizky Nugraha'!$G$5:$G$54,"Sudah")+COUNTIF('Muhammad Akbar Putra'!$G$5:$G$54,"Sudah")+COUNTIF('Muhammad Hafidz Ramadhan'!$G$5:$G$54,"Sudah")+COUNTIF('Muhammad Lutfhi Mubarrok'!$G$5:$G$54,"Sudah")+COUNTIF('Muhammad Nadhira Shafar'!$G$5:$G$54,"Sudah")+COUNTIF('Muhammad Rafi Fakhrul Aiman'!$G$5:$G$54,"Sudah")+COUNTIF('Muhammad Reyvin Aryaguna'!$G$5:$G$54,"Sudah")+COUNTIF('Nadzar Akbar Subagja'!$G$5:$G$54,"Sudah")+COUNTIF('Najwan Muhammad Ghalib'!$G$5:$G$54,"Sudah")+COUNTIF('Nia Rizkiyanti'!$G$5:$G$54,"Sudah")+COUNTIF('Nur Ainillah Nabawi'!$G$5:$G$54,"Sudah")+COUNTIF('Nurul Khairunnissa'!$G$5:$G$54,"Sudah")+COUNTIF('Putri Maharani'!$G$5:$G$54,"Sudah")+COUNTIF('Rika Kartika'!$G$5:$G$54,"Sudah")+COUNTIF('Riva Nur Fathiya Safitri'!$G$5:$G$54,"Sudah")+COUNTIF('Shintia Nur Fadillah'!$G$5:$G$54,"Sudah")+COUNTIF('Sinta Faoziah'!$G$5:$G$54,"Sudah")+COUNTIF('Tiara Anastasya Gumilar'!$G$5:$G$54,"Sudah")+COUNTIF('Tiara Maelani'!$G$5:$G$54,"Sudah") | N6: =COUNTIF('Aina Triyana Anggraini'!$G$5:$G$54,"Belum")+COUNTIF('Aldi Suryadinata'!$G$5:$G$54,"Belum")+COUNTIF('Asyahlan Hielmy'!$G$5:$G$54,"Belum")+COUNTIF('Asyira Nur Haida'!$G$5:$G$54,"Belum")+COUNTIF('Bayu Rizki Alfarizi'!$G$5:$G$54,"Belum")+COUNTIF('Chandanie Nely Agustin'!$G$5:$G$54,"Belum")+COUNTIF('Dida Zein Risty'!$G$5:$G$54,"Belum")+COUNTIF('Fadil Rijatul Haq'!$G$5:$G$54,"Belum")+COUNTIF('Faega Fitriani Dwi Putri'!$G$5:$G$54,"Belum")+COUNTIF('Fajri Rizki Robbani'!$G$5:$G$54,"Belum")+COUNTIF('Fakhri Safrudin Sopandi'!$G$5:$G$54,"Belum")+COUNTIF('Moh. Rizky Nugraha'!$G$5:$G$54,"Belum")+COUNTIF('Muhammad Akbar Putra'!$G$5:$G$54,"Belum")+COUNTIF('Muhammad Hafidz Ramadhan'!$G$5:$G$54,"Belum")+COUNTIF('Muhammad Lutfhi Mubarrok'!$G$5:$G$54,"Belum")+COUNTIF('Muhammad Nadhira Shafar'!$G$5:$G$54,"Belum")+COUNTIF('Muhammad Rafi Fakhrul Aiman'!$G$5:$G$54,"Belum")+COUNTIF('Muhammad Reyvin Aryaguna'!$G$5:$G$54,"Belum")+COUNTIF('Nadzar Akbar Subagja'!$G$5:$G$54,"Belum")+COUNTIF('Najwan Muhammad Ghalib'!$G$5:$G$54,"Belum")+COUNTIF('Nia Rizkiyanti'!$G$5:$G$54,"Belum")+COUNTIF('Nur Ainillah Nabawi'!$G$5:$G$54,"Belum")+COUNTIF('Nurul Khairunnissa'!$G$5:$G$54,"Belum")+COUNTIF('Putri Maharani'!$G$5:$G$54,"Belum")+COUNTIF('Rika Kartika'!$G$5:$G$54,"Belum")+COUNTIF('Riva Nur Fathiya Safitri'!$G$5:$G$54,"Belum")+COUNTIF('Shintia Nur Fadillah'!$G$5:$G$54,"Belum")+COUNTIF('Sinta Faoziah'!$G$5:$G$54,"Belum")+COUNTIF('Tiara Anastasya Gumilar'!$G$5:$G$54,"Belum")+COUNTIF('Tiara Maelani'!$G$5:$G$54,"Belum")
B8: nama terisi di 30 tab coach | F8: tab coach aktif | J8: keselamatan ke ortu: Sudah | N8: keselamatan ke ortu: Belum
B10: SEBARAN SISWA
B27: PROGRAM & RISIKO
B44: LOKASI & KOLAM (DARI TABEL JADWAL)
B68: RINGKASAN ANGKA
B69: Status PA | D69: ='Data Dashboard'!H17 | J69: Program belum diisi | L69: ='Data Dashboard'!E10
B70: Status Standalone | D70: ='Data Dashboard'!H18 | J70: Risiko belum diisi | L70: ='Data Dashboard'!H7
B71: Level belum diisi | D71: ='Data Dashboard'!B19 | J71: Sosialisasi belum diisi | L71: ='Data Dashboard'!H13
B74: Privasi: dashboard hanya menampilkan angka agregat - tanpa nama siswa.
B75: Catatan: grafik Lokasi & Kolam menghitung baris jadwal yang diisi di tabel kanan tiap tab coach; Top 8 coach dihitung dari jumlah nama di tiap tab.

Sheet Member Aktif
A1: TWENTY SWIM - DAFTAR MEMBER AKTIF
A2: Gabungan semua siswa dari 30 tab coach, urut abjad. Pilih filter di bawah (kosongkan = tampilkan semua).
A3: Coach: | C3: Program: | E3: Level:
A4: Ditampilkan: | B4: =COUNTA($B$6:$B$2000) | C4: siswa
A5: Nama Siswa | B5: Coach | C5: Program/Kelas | D5: Level
A6: =IFERROR(FILTER(DataMember!$A$2:$D$2000,DataMember!$A$2:$A$2000<>"",(((DataMember!$B$2:$B$2000=$B$3)+($B$3=""))>0),(((DataMember!$C$2:$C$2000=$D$3)+($D$3=""))>0),(((DataMember!$D$2:$D$2000=$F$3)+($F$3=""))>0)),"Tidak ada siswa untuk filter ini.")

Sheet Panduan Level SSI
A1: PANDUAN LEVEL SSI (SWIM SCHOOL INTERNATIONAL)
A3: Kategori | B3: Level | C3: Rentang Usia | E3: PROGRAM / KELAS
A4: Baby Swim | B4: Baby Swim I | C4: 3 bulan - 2 thn 11 bln | E4: Program | F4: Warna di tab coach
A5: Baby Swim | B5: Baby Swim II | C5: 3 bulan - 2 thn 11 bln | E5: Private Class | F5: Biru muda
A6: Aquatike | B6: Aquatike I | C6: 3 thn - 4 thn 11 bln | E6: Couple Class | F6: Biru muda
A7: Aquatike | B7: Aquatike II | C7: 3 thn - 4 thn 11 bln | E7: Group Class | F7: Biru muda
A8: Aquatike | B8: Aquatike III | C8: 3 thn - 4 thn 11 bln | E8: Reguler Class | F8: Biru muda
A9: Preschool | B9: Preschool I | C9: 5 thn - 6 thn | E9: Baby Swim | F9: Merah muda
A10: Preschool | B10: Preschool II | C10: 5 thn - 6 thn | E10: Hydrotherapy Class | F10: Merah muda
A11: Beginner | B11: Beginner I | C11: 6 thn - dewasa
A12: Beginner | B12: Beginner II | C12: 6 thn - dewasa | E12: RISIKO & SOSIALISASI
A13: Beginner | B13: Beginner III | C13: 6 thn - dewasa | E13: Nilai | F13: Warna
A14: Intermediate | B14: Intermediate I | C14: 6 thn - dewasa | E14: Risiko: Rendah | F14: otomatis saat dipilih
A15: Intermediate | B15: Intermediate II | C15: 6 thn - dewasa | E15: Risiko: Sedang | F15: otomatis saat dipilih
A16: Advanced | B16: Advanced I | C16: 6 thn - dewasa | E16: Risiko: Tinggi | F16: otomatis saat dipilih
A17: Advanced | B17: Advanced II | C17: 6 thn - dewasa | E17: Sosialisasi: Sudah | F17: otomatis saat dipilih
A18: Swim Team Prep | B18: Swim Team Prep | C18: Transisi atlet kompetitif | E18: Sosialisasi: Belum | F18: otomatis saat dipilih
A21: KETERANGAN STATUS | E21: CARA PAKAI FILE INI
A22: Status | B22: Keterangan | E22: 1. Isi data hanya di tab coach (kolom putih). Kolom dropdown tinggal pilih.
A23: PA (Parent Assist) | B23: Ada pendamping di air | E23: 2. Kolom No dan Coach terisi otomatis - jangan diketik manual.
A24: Standalone | B24: Mandiri tanpa pendamping | E24: 3. Tabel kanan di tiap tab coach adalah jadwal latihan: isi Jam, Nama Siswa, Lokasi, Kolam.
E25: 4. Tab DASHBOARD dan Member Aktif menghitung sendiri dari 30 tab coach.
E26: 5. Tab Member Aktif: pilih Coach / Program / Level untuk menyaring; kosongkan untuk semua.
E27: 6. Tab DataMember, Data Dashboard, dan Daftar disembunyikan (sumber rumus & dropdown). Jangan diubah.
E28: 7. Rumus SORT + FILTER di Member Aktif dibuat untuk Google Sheets (Excel 365 juga mendukung).
E29: Sumber data awal: Database_Siswa_Twenty_SSI.xlsx (Nama, Level Saat Ini, Status) per tab coach.
E30: Program/Kelas diisi otomatis hanya jika ada petunjuk di data asal, mis. '(Private)', '(Grup)',
E31: '(Couple)', 'Swim/Hydro Therapy' -> Hydrotherapy Class, level Baby Swim -> Baby Swim. Sisanya kosong.

Sheet Aina Triyana Anggraini
A1: TWENTY SWIM - LEVEL SISWA & JADWAL LATIHAN (BANDUNG)
A2: Pelatih: Aina Triyana Anggraini | D2: Terisi: | E2: =COUNTA($B$5:$B$54) | F2: siswa
A3: Isi kolom putih. Kolom berwarna = dropdown, tinggal pilih. No & Coach terisi otomatis.
A4: No | B4: Nama Siswa | C4: Program/Kelas | D4: Level Saat Ini | E4: Status | F4: Risiko | G4: Sosialisasi Keselamatan ke Ortu | H4: Coach | J4: JADWAL LATIHAN (Senin-Jumat 5 baris, Sabtu-Minggu 10 baris)
A5: =IF($B5<>"",ROW()-4,"") | B5: Nazeeva Hulwa Elzanitha | C5: Baby Swim | D5: Baby Swim I | E5: PA | H5: =IF($B5<>"","Aina Triyana Anggraini","") | J5: Hari | K5: Jam | L5: Nama Siswa | M5: Lokasi (wilayah) | N5: Kolam
A6: =IF($B6<>"",ROW()-4,"") | B6: Askara Al Biruni | C6: Baby Swim | D6: Baby Swim I | E6: PA | H6: =IF($B6<>"","Aina Triyana Anggraini","") | J6: Senin
A7: =IF($B7<>"",ROW()-4,"") | B7: Sakina | D7: Preschool I | E7: Standalone | H7: =IF($B7<>"","Aina Triyana Anggraini","")
A8: =IF($B8<>"",ROW()-4,"") | B8: Lubna | D8: Preschool I | E8: Standalone | H8: =IF($B8<>"","Aina Triyana Anggraini","")
A9: =IF($B9<>"",ROW()-4,"") | B9: Finna | D9: Aquatike I | E9: Standalone | H9: =IF($B9<>"","Aina Triyana Anggraini","")
A10: =IF($B10<>"",ROW()-4,"") | B10: Falisha | D10: Preschool I | E10: Standalone | H10: =IF($B10<>"","Aina Triyana Anggraini","")
A11: =IF($B11<>"",ROW()-4,"") | B11: Medina | D11: Aquatike I | E11: Standalone | H11: =IF($B11<>"","Aina Triyana Anggraini","") | J11: Selasa
A12: =IF($B12<>"",ROW()-4,"") | B12: Jennaira | D12: Aquatike I | E12: Standalone | H12: =IF($B12<>"","Aina Triyana Anggraini","")
A13: =IF($B13<>"",ROW()-4,"") | B13: Mikayla | D13: Preschool I | E13: Standalone | H13: =IF($B13<>"","Aina Triyana Anggraini","")
A14: =IF($B14<>"",ROW()-4,"") | H14: =IF($B14<>"","Aina Triyana Anggraini","")
A15: =IF($B15<>"",ROW()-4,"") | H15: =IF($B15<>"","Aina Triyana Anggraini","")
A16: =IF($B16<>"",ROW()-4,"") | H16: =IF($B16<>"","Aina Triyana Anggraini","") | J16: Rabu
A17: =IF($B17<>"",ROW()-4,"") | H17: =IF($B17<>"","Aina Triyana Anggraini","")
A18: =IF($B18<>"",ROW()-4,"") | H18: =IF($B18<>"","Aina Triyana Anggraini","")
A19: =IF($B19<>"",ROW()-4,"") | H19: =IF($B19<>"","Aina Triyana Anggraini","")
A20: =IF($B20<>"",ROW()-4,"") | H20: =IF($B20<>"","Aina Triyana Anggraini","")
A21: =IF($B21<>"",ROW()-4,"") | H21: =IF($B21<>"","Aina Triyana Anggraini","") | J21: Kamis
A22: =IF($B22<>"",ROW()-4,"") | H22: =IF($B22<>"","Aina Triyana Anggraini","")
A23: =IF($B23<>"",ROW()-4,"") | H23: =IF($B23<>"","Aina Triyana Anggraini","")
A24: =IF($B24<>"",ROW()-4,"") | H24: =IF($B24<>"","Aina Triyana Anggraini","")
A25: =IF($B25<>"",ROW()-4,"") | H25: =IF($B25<>"","Aina Triyana Anggraini","")
A26: =IF($B26<>"",ROW()-4,"") | H26: =IF($B26<>"","Aina Triyana Anggraini","") | J26: Jumat
A27: =IF($B27<>"",ROW()-4,"") | H27: =IF($B27<>"","Aina Triyana Anggraini","")
A28: =IF($B28<>"",ROW()-4,"") | H28: =IF($B28<>"","Aina Triyana Anggraini","")
A29: =IF($B29<>"",ROW()-4,"") | H29: =IF($B29<>"","Aina Triyana Anggraini","")
A30: =IF($B30<>"",ROW()-4,"") | H30: =IF($B30<>"","Aina Triyana Anggraini","")
A31: =IF($B31<>"",ROW()-4,"") | H31: =IF($B31<>"","Aina Triyana Anggraini","") | J31: Sabtu
A32: =IF($B32<>"",ROW()-4,"") | H32: =IF($B32<>"","Aina Triyana Anggraini","")
A33: =IF($B33<>"",ROW()-4,"") | H33: =IF($B33<>"","Aina Triyana Anggraini","")
A34: =IF($B34<>"",ROW()-4,"") | H34: =IF($B34<>"","Aina Triyana Anggraini","")
A35: =IF($B35<>"",ROW()-4,"") | H35: =IF($B35<>"","Aina Triyana Anggraini","")
A36: =IF($B36<>"",ROW()-4,"") | H36: =IF($B36<>"","Aina Triyana Anggraini","")
A37: =IF($B37<>"",ROW()-4,"") | H37: =IF($B37<>"","Aina Triyana Anggraini","")
A38: =IF($B38<>"",ROW()-4,"") | H38: =IF($B38<>"","Aina Triyana Anggraini","")
A39: =IF($B39<>"",ROW()-4,"") | H39: =IF($B39<>"","Aina Triyana Anggraini","")
A40: =IF($B40<>"",ROW()-4,"") | H40: =IF($B40<>"","Aina Triyana Anggraini","")
...

Sheet Aldi Suryadinata
A1: TWENTY SWIM - LEVEL SISWA & JADWAL LATIHAN (BANDUNG)
A2: Pelatih: Aldi Suryadinata | D2: Terisi: | E2: =COUNTA($B$5:$B$54) | F2: siswa
A3: Isi kolom putih. Kolom berwarna = dropdown, tinggal pilih. No & Coach terisi otomatis.
A4: No | B4: Nama Siswa | C4: Program/Kelas | D4: Level Saat Ini | E4: Status | F4: Risiko | G4: Sosialisasi Keselamatan ke Ortu | H4: Coach | J4: JADWAL LATIHAN (Senin-Jumat 5 baris, Sabtu-Minggu 10 baris)
A5: =IF($B5<>"",ROW()-4,"") | B5: Elvano | D5: Aquatike I | E5: PA | H5: =IF($B5<>"","Aldi Suryadinata","") | J5: Hari | K5: Jam | L5: Nama Siswa | M5: Lokasi (wilayah) | N5: Kolam
A6: =IF($B6<>"",ROW()-4,"") | B6: Rajendra | D6: Aquatike II | E6: Standalone | H6: =IF($B6<>"","Aldi Suryadinata","") | J6: Senin
A7: =IF($B7<>"",ROW()-4,"") | B7: Fathan | D7: Beginner II | E7: Standalone | H7: =IF($B7<>"","Aldi Suryadinata","")
A8: =IF($B8<>"",ROW()-4,"") | B8: Khalid | D8: Aquatike II | E8: Standalone | H8: =IF($B8<>"","Aldi Suryadinata","")
A9: =IF($B9<>"",ROW()-4,"") | B9: Khafi | D9: Aquatike II | E9: Standalone | H9: =IF($B9<>"","Aldi Suryadinata","")
A10: =IF($B10<>"",ROW()-4,"") | B10: Arshad | D10: Beginner I | H10: =IF($B10<>"","Aldi Suryadinata","")
A11: =IF($B11<>"",ROW()-4,"") | H11: =IF($B11<>"","Aldi Suryadinata","") | J11: Selasa
A12: =IF($B12<>"",ROW()-4,"") | H12: =IF($B12<>"","Aldi Suryadinata","")
A13: =IF($B13<>"",ROW()-4,"") | H13: =IF($B13<>"","Aldi Suryadinata","")
A14: =IF($B14<>"",ROW()-4,"") | H14: =IF($B14<>"","Aldi Suryadinata","")
A15: =IF($B15<>"",ROW()-4,"") | H15: =IF($B15<>"","Aldi Suryadinata","")
A16: =IF($B16<>"",ROW()-4,"") | H16: =IF($B16<>"","Aldi Suryadinata","") | J16: Rabu
A17: =IF($B17<>"",ROW()-4,"") | H17: =IF($B17<>"","Aldi Suryadinata","")
A18: =IF($B18<>"",ROW()-4,"") | H18: =IF($B18<>"","Aldi Suryadinata","")
A19: =IF($B19<>"",ROW()-4,"") | H19: =IF($B19<>"","Aldi Suryadinata","")
A20: =IF($B20<>"",ROW()-4,"") | H20: =IF($B20<>"","Aldi Suryadinata","")
A21: =IF($B21<>"",ROW()-4,"") | H21: =IF($B21<>"","Aldi Suryadinata","") | J21: Kamis
A22: =IF($B22<>"",ROW()-4,"") | H22: =IF($B22<>"","Aldi Suryadinata","")
A23: =IF($B23<>"",ROW()-4,"") | H23: =IF($B23<>"","Aldi Suryadinata","")
A24: =IF($B24<>"",ROW()-4,"") | H24: =IF($B24<>"","Aldi Suryadinata","")
A25: =IF($B25<>"",ROW()-4,"") | H25: =IF($B25<>"","Aldi Suryadinata","")
A26: =IF($B26<>"",ROW()-4,"") | H26: =IF($B26<>"","Aldi Suryadinata","") | J26: Jumat
A27: =IF($B27<>"",ROW()-4,"") | H27: =IF($B27<>"","Aldi Suryadinata","")
A28: =IF($B28<>"",ROW()-4,"") | H28: =IF($B28<>"","Aldi Suryadinata","")
A29: =IF($B29<>"",ROW()-4,"") | H29: =IF($B29<>"","Aldi Suryadinata","")
A30: =IF($B30<>"",ROW()-4,"") | H30: =IF($B30<>"","Aldi Suryadinata","")
A31: =IF($B31<>"",ROW()-4,"") | H31: =IF($B31<>"","Aldi Suryadinata","") | J31: Sabtu
A32: =IF($B32<>"",ROW()-4,"") | H32: =IF($B32<>"","Aldi Suryadinata","")
A33: =IF($B33<>"",ROW()-4,"") | H33: =IF($B33<>"","Aldi Suryadinata","")
A34: =IF($B34<>"",ROW()-4,"") | H34: =IF($B34<>"","Aldi Suryadinata","")
A35: =IF($B35<>"",ROW()-4,"") | H35: =IF($B35<>"","Aldi Suryadinata","")
A36: =IF($B36<>"",ROW()-4,"") | H36: =IF($B36<>"","Aldi Suryadinata","")
A37: =IF($B37<>"",ROW()-4,"") | H37: =IF($B37<>"","Aldi Suryadinata","")
A38: =IF($B38<>"",ROW()-4,"") | H38: =IF($B38<>"","Aldi Suryadinata","")
A39: =IF($B39<>"",ROW()-4,"") | H39: =IF($B39<>"","Aldi Suryadinata","")
A40: =IF($B40<>"",ROW()-4,"") | H40: =IF($B40<>"","Aldi Suryadinata","")
...

Sheet Asyahlan Hielmy
A1: TWENTY SWIM - LEVEL SISWA & JADWAL LATIHAN (BANDUNG)
A2: Pelatih: Asyahlan Hielmy | D2: Terisi: | E2: =COUNTA($B$5:$B$54) | F2: siswa
A3: Isi kolom putih. Kolom berwarna = dropdown, tinggal pilih. No & Coach terisi otomatis.
A4: No | B4: Nama Siswa | C4: Program/Kelas | D4: Level Saat Ini | E4: Status | F4: Risiko | G4: Sosialisasi Keselamatan ke Ortu | H4: Coach | J4: JADWAL LATIHAN (Senin-Jumat 5 baris, Sabtu-Minggu 10 baris)
A5: =IF($B5<>"",ROW()-4,"") | B5: Muhammad Zaki Faturrahman (Private) | C5: Private Class | D5: Intermediate I | E5: Standalone | H5: =IF($B5<>"","Asyahlan Hielmy","") | J5: Hari | K5: Jam | L5: Nama Siswa | M5: Lokasi (wilayah) | N5: Kolam
A6: =IF($B6<>"",ROW()-4,"") | B6: Ibrahim (Private) | C6: Private Class | D6: Intermediate I | E6: Standalone | H6: =IF($B6<>"","Asyahlan Hielmy","") | J6: Senin
A7: =IF($B7<>"",ROW()-4,"") | B7: Kirana (Grup) | C7: Group Class | D7: Preschool II | E7: Standalone | H7: =IF($B7<>"","Asyahlan Hielmy","")
A8: =IF($B8<>"",ROW()-4,"") | B8: Qinara (Grup) | C8: Group Class | D8: Preschool II | E8: Standalone | H8: =IF($B8<>"","Asyahlan Hielmy","")
A9: =IF($B9<>"",ROW()-4,"") | B9: Neima (Grup) | C9: Group Class | D9: Beginner II | E9: Standalone | H9: =IF($B9<>"","Asyahlan Hielmy","")
A10: =IF($B10<>"",ROW()-4,"") | B10: Abrizam (Private) | C10: Private Class | D10: Beginner I | E10: Standalone | H10: =IF($B10<>"","Asyahlan Hielmy","")
A11: =IF($B11<>"",ROW()-4,"") | B11: Raffasya (Private) | C11: Private Class | D11: Beginner I | E11: Standalone | H11: =IF($B11<>"","Asyahlan Hielmy","") | J11: Selasa
A12: =IF($B12<>"",ROW()-4,"") | B12: Rasyid (Private) | C12: Private Class | D12: Beginner I | E12: Standalone | H12: =IF($B12<>"","Asyahlan Hielmy","")
A13: =IF($B13<>"",ROW()-4,"") | B13: Irzany Kautsar Hanan Ubaidillah (Private) | C13: Private Class | D13: Beginner I | E13: PA | H13: =IF($B13<>"","Asyahlan Hielmy","")
A14: =IF($B14<>"",ROW()-4,"") | B14: Izdihar Uwais Ubaidillah | D14: Aquatike I | E14: PA | H14: =IF($B14<>"","Asyahlan Hielmy","")
A15: =IF($B15<>"",ROW()-4,"") | B15: Janitra (Private) | C15: Private Class | D15: Aquatike I | E15: Standalone | H15: =IF($B15<>"","Asyahlan Hielmy","")
A16: =IF($B16<>"",ROW()-4,"") | B16: Abbasy (Private) | C16: Private Class | D16: Aquatike I | E16: PA | H16: =IF($B16<>"","Asyahlan Hielmy","") | J16: Rabu
A17: =IF($B17<>"",ROW()-4,"") | B17: Ghava (Private Summarecon) | C17: Private Class | D17: Aquatike I | E17: PA | H17: =IF($B17<>"","Asyahlan Hielmy","")
A18: =IF($B18<>"",ROW()-4,"") | B18: Keihan (Private Summarecon) | C18: Private Class | D18: Preschool I | E18: Standalone | H18: =IF($B18<>"","Asyahlan Hielmy","")
A19: =IF($B19<>"",ROW()-4,"") | B19: Fahri (Private) | C19: Private Class | D19: Beginner I | H19: =IF($B19<>"","Asyahlan Hielmy","")
A20: =IF($B20<>"",ROW()-4,"") | B20: Kennan(Couple Summarecon) | C20: Couple Class | D20: Intermediate I | E20: Standalone | H20: =IF($B20<>"","Asyahlan Hielmy","")
A21: =IF($B21<>"",ROW()-4,"") | B21: Kayvan (Couple Summarecon) | C21: Couple Class | D21: Intermediate I | E21: Standalone | H21: =IF($B21<>"","Asyahlan Hielmy","") | J21: Kamis
A22: =IF($B22<>"",ROW()-4,"") | B22: Liam (Private | C22: Private Class | D22: Beginner I | E22: Standalone | H22: =IF($B22<>"","Asyahlan Hielmy","")
A23: =IF($B23<>"",ROW()-4,"") | B23: Ken (Private) | C23: Private Class | D23: Beginner I | E23: PA | H23: =IF($B23<>"","Asyahlan Hielmy","")
A24: =IF($B24<>"",ROW()-4,"") | B24: Asha (Group) | C24: Group Class | D24: Beginner I | E24: PA | H24: =IF($B24<>"","Asyahlan Hielmy","")
A25: =IF($B25<>"",ROW()-4,"") | B25: Alya (Group) | C25: Group Class | D25: Beginner I | E25: Standalone | H25: =IF($B25<>"","Asyahlan Hielmy","")
A26: =IF($B26<>"",ROW()-4,"") | B26: Raiq (Group ) | C26: Group Class | D26: Beginner I | E26: Standalone | H26: =IF($B26<>"","Asyahlan Hielmy","") | J26: Jumat
A27: =IF($B27<>"",ROW()-4,"") | B27: Gendis (Group) | C27: Group Class | D27: Beginner I | E27: Standalone | H27: =IF($B27<>"","Asyahlan Hielmy","")
A28: =IF($B28<>"",ROW()-4,"") | B28: Zaid (Swim Therapy) | C28: Hydrotherapy Class | H28: =IF($B28<>"","Asyahlan Hielmy","")
A29: =IF($B29<>"",ROW()-4,"") | B29: Rafanza (Private) | C29: Private Class | D29: Aquatike I | E29: PA | H29: =IF($B29<>"","Asyahlan Hielmy","")
A30: =IF($B30<>"",ROW()-4,"") | B30: Balista | D30: Beginner I | E30: PA | H30: =IF($B30<>"","Asyahlan Hielmy","")
A31: =IF($B31<>"",ROW()-4,"") | B31: Alfath (couple Summarecon) | C31: Couple Class | D31: Beginner I | E31: Standalone | H31: =IF($B31<>"","Asyahlan Hielmy","") | J31: Sabtu
A32: =IF($B32<>"",ROW()-4,"") | B32: Hafidz (couple Summarecon ) | C32: Couple Class | H32: =IF($B32<>"","Asyahlan Hielmy","")
A33: =IF($B33<>"",ROW()-4,"") | B33: Banafasha | H33: =IF($B33<>"","Asyahlan Hielmy","")
A34: =IF($B34<>"",ROW()-4,"") | B34: Zevanya | H34: =IF($B34<>"","Asyahlan Hielmy","")
A35: =IF($B35<>"",ROW()-4,"") | B35: Arkyssa | H35: =IF($B35<>"","Asyahlan Hielmy","")
A36: =IF($B36<>"",ROW()-4,"") | B36: kendaru | H36: =IF($B36<>"","Asyahlan Hielmy","")
A37: =IF($B37<>"",ROW()-4,"") | H37: =IF($B37<>"","Asyahlan Hielmy","")
A38: =IF($B38<>"",ROW()-4,"") | H38: =IF($B38<>"","Asyahlan Hielmy","")
A39: =IF($B39<>"",ROW()-4,"") | H39: =IF($B39<>"","Asyahlan Hielmy","")
A40: =IF($B40<>"",ROW()-4,"") | H40: =IF($B40<>"","Asyahlan Hielmy","")
...

Sheet Asyira Nur Haida
A1: TWENTY SWIM - LEVEL SISWA & JADWAL LATIHAN (BANDUNG)
A2: Pelatih: Asyira Nur Haida | D2: Terisi: | E2: =COUNTA($B$5:$B$54) | F2: siswa
A3: Isi kolom putih. Kolom berwarna = dropdown, tinggal pilih. No & Coach terisi otomatis.
A4: No | B4: Nama Siswa | C4: Program/Kelas | D4: Level Saat Ini | E4: Status | F4: Risiko | G4: Sosialisasi Keselamatan ke Ortu | H4: Coach | J4: JADWAL LATIHAN (Senin-Jumat 5 baris, Sabtu-Minggu 10 baris)
A5: =IF($B5<>"",ROW()-4,"") | B5: Risti Dawara Ayudhia | D5: Beginner II | E5: Standalone | H5: =IF($B5<>"","Asyira Nur Haida","") | J5: Hari | K5: Jam | L5: Nama Siswa | M5: Lokasi (wilayah) | N5: Kolam
A6: =IF($B6<>"",ROW()-4,"") | B6: Putri Alit Dawara | D6: Beginner II | E6: Standalone | H6: =IF($B6<>"","Asyira Nur Haida","") | J6: Senin
A7: =IF($B7<>"",ROW()-4,"") | B7: Mutiara Adinda Dawara | D7: Beginner I | E7: Standalone | H7: =IF($B7<>"","Asyira Nur Haida","")
A8: =IF($B8<>"",ROW()-4,"") | B8: Callista Nayanika Sudarsono | D8: Preschool II | E8: PA | H8: =IF($B8<>"","Asyira Nur Haida","")
A9: =IF($B9<>"",ROW()-4,"") | B9: Prisia Gendis Nugroho | D9: Beginner I | E9: PA | H9: =IF($B9<>"","Asyira Nur Haida","")
A10: =IF($B10<>"",ROW()-4,"") | B10: Shafiya Frea Almaira | D10: Aquatike I | E10: PA | H10: =IF($B10<>"","Asyira Nur Haida","")
A11: =IF($B11<>"",ROW()-4,"") | B11: Aziela Azzahra | D11: Beginner II | E11: Standalone | H11: =IF($B11<>"","Asyira Nur Haida","") | J11: Selasa
A12: =IF($B12<>"",ROW()-4,"") | B12: Giovanni Anggara Gunawan | D12: Preschool I | E12: PA | H12: =IF($B12<>"","Asyira Nur Haida","")
A13: =IF($B13<>"",ROW()-4,"") | H13: =IF($B13<>"","Asyira Nur Haida","")
A14: =IF($B14<>"",ROW()-4,"") | H14: =IF($B14<>"","Asyira Nur Haida","")
A15: =IF($B15<>"",ROW()-4,"") | H15: =IF($B15<>"","Asyira Nur Haida","")
A16: =IF($B16<>"",ROW()-4,"") | H16: =IF($B16<>"","Asyira Nur Haida","") | J16: Rabu
A17: =IF($B17<>"",ROW()-4,"") | H17: =IF($B17<>"","Asyira Nur Haida","")
A18: =IF($B18<>"",ROW()-4,"") | H18: =IF($B18<>"","Asyira Nur Haida","")
A19: =IF($B19<>"",ROW()-4,"") | H19: =IF($B19<>"","Asyira Nur Haida","")
A20: =IF($B20<>"",ROW()-4,"") | H20: =IF($B20<>"","Asyira Nur Haida","")
A21: =IF($B21<>"",ROW()-4,"") | H21: =IF($B21<>"","Asyira Nur Haida","") | J21: Kamis
A22: =IF($B22<>"",ROW()-4,"") | H22: =IF($B22<>"","Asyira Nur Haida","")
A23: =IF($B23<>"",ROW()-4,"") | H23: =IF($B23<>"","Asyira Nur Haida","")
A24: =IF($B24<>"",ROW()-4,"") | H24: =IF($B24<>"","Asyira Nur Haida","")
A25: =IF($B25<>"",ROW()-4,"") | H25: =IF($B25<>"","Asyira Nur Haida","")
A26: =IF($B26<>"",ROW()-4,"") | H26: =IF($B26<>"","Asyira Nur Haida","") | J26: Jumat
A27: =IF($B27<>"",ROW()-4,"") | H27: =IF($B27<>"","Asyira Nur Haida","")
A28: =IF($B28<>"",ROW()-4,"") | H28: =IF($B28<>"","Asyira Nur Haida","")
A29: =IF($B29<>"",ROW()-4,"") | H29: =IF($B29<>"","Asyira Nur Haida","")
A30: =IF($B30<>"",ROW()-4,"") | H30: =IF($B30<>"","Asyira Nur Haida","")
A31: =IF($B31<>"",ROW()-4,"") | H31: =IF($B31<>"","Asyira Nur Haida","") | J31: Sabtu
A32: =IF($B32<>"",ROW()-4,"") | H32: =IF($B32<>"","Asyira Nur Haida","")
A33: =IF($B33<>"",ROW()-4,"") | H33: =IF($B33<>"","Asyira Nur Haida","")
A34: =IF($B34<>"",ROW()-4,"") | H34: =IF($B34<>"","Asyira Nur Haida","")
A35: =IF($B35<>"",ROW()-4,"") | H35: =IF($B35<>"","Asyira Nur Haida","")
A36: =IF($B36<>"",ROW()-4,"") | H36: =IF($B36<>"","Asyira Nur Haida","")
A37: =IF($B37<>"",ROW()-4,"") | H37: =IF($B37<>"","Asyira Nur Haida","")
A38: =IF($B38<>"",ROW()-4,"") | H38: =IF($B38<>"","Asyira Nur Haida","")
A39: =IF($B39<>"",ROW()-4,"") | H39: =IF($B39<>"","Asyira Nur Haida","")
A40: =IF($B40<>"",ROW()-4,"") | H40: =IF($B40<>"","Asyira Nur Haida","")
...

Sheet Bayu Rizki Alfarizi
A1: TWENTY SWIM - LEVEL SISWA & JADWAL LATIHAN (BANDUNG)
A2: Pelatih: Bayu Rizki Alfarizi | D2: Terisi: | E2: =COUNTA($B$5:$B$54) | F2: siswa
A3: Isi kolom putih. Kolom berwarna = dropdown, tinggal pilih. No & Coach terisi otomatis.
A4: No | B4: Nama Siswa | C4: Program/Kelas | D4: Level Saat Ini | E4: Status | F4: Risiko | G4: Sosialisasi Keselamatan ke Ortu | H4: Coach | J4: JADWAL LATIHAN (Senin-Jumat 5 baris, Sabtu-Minggu 10 baris)
A5: =IF($B5<>"",ROW()-4,"") | B5: Akifa Medina Ahmad | D5: Intermediate II | E5: Standalone | H5: =IF($B5<>"","Bayu Rizki Alfarizi","") | J5: Hari | K5: Jam | L5: Nama Siswa | M5: Lokasi (wilayah) | N5: Kolam
A6: =IF($B6<>"",ROW()-4,"") | H6: =IF($B6<>"","Bayu Rizki Alfarizi","") | J6: Senin
A7: =IF($B7<>"",ROW()-4,"") | H7: =IF($B7<>"","Bayu Rizki Alfarizi","")
A8: =IF($B8<>"",ROW()-4,"") | H8: =IF($B8<>"","Bayu Rizki Alfarizi","")
A9: =IF($B9<>"",ROW()-4,"") | H9: =IF($B9<>"","Bayu Rizki Alfarizi","")
A10: =IF($B10<>"",ROW()-4,"") | H10: =IF($B10<>"","Bayu Rizki Alfarizi","")
A11: =IF($B11<>"",ROW()-4,"") | H11: =IF($B11<>"","Bayu Rizki Alfarizi","") | J11: Selasa
A12: =IF($B12<>"",ROW()-4,"") | H12: =IF($B12<>"","Bayu Rizki Alfarizi","")
A13: =IF($B13<>"",ROW()-4,"") | H13: =IF($B13<>"","Bayu Rizki Alfarizi","")
A14: =IF($B14<>"",ROW()-4,"") | H14: =IF($B14<>"","Bayu Rizki Alfarizi","")
A15: =IF($B15<>"",ROW()-4,"") | H15: =IF($B15<>"","Bayu Rizki Alfarizi","")
A16: =IF($B16<>"",ROW()-4,"") | H16: =IF($B16<>"","Bayu Rizki Alfarizi","") | J16: Rabu
A17: =IF($B17<>"",ROW()-4,"") | H17: =IF($B17<>"","Bayu Rizki Alfarizi","")
A18: =IF($B18<>"",ROW()-4,"") | H18: =IF($B18<>"","Bayu Rizki Alfarizi","")
A19: =IF($B19<>"",ROW()-4,"") | H19: =IF($B19<>"","Bayu Rizki Alfarizi","")
A20: =IF($B20<>"",ROW()-4,"") | H20: =IF($B20<>"","Bayu Rizki Alfarizi","")
A21: =IF($B21<>"",ROW()-4,"") | H21: =IF($B21<>"","Bayu Rizki Alfarizi","") | J21: Kamis
A22: =IF($B22<>"",ROW()-4,"") | H22: =IF($B22<>"","Bayu Rizki Alfarizi","")
A23: =IF($B23<>"",ROW()-4,"") | H23: =IF($B23<>"","Bayu Rizki Alfarizi","")
A24: =IF($B24<>"",ROW()-4,"") | H24: =IF($B24<>"","Bayu Rizki Alfarizi","")
A25: =IF($B25<>"",ROW()-4,"") | H25: =IF($B25<>"","Bayu Rizki Alfarizi","")
A26: =IF($B26<>"",ROW()-4,"") | H26: =IF($B26<>"","Bayu Rizki Alfarizi","") | J26: Jumat
A27: =IF($B27<>"",ROW()-4,"") | H27: =IF($B27<>"","Bayu Rizki Alfarizi","")
A28: =IF($B28<>"",ROW()-4,"") | H28: =IF($B28<>"","Bayu Rizki Alfarizi","")
A29: =IF($B29<>"",ROW()-4,"") | H29: =IF($B29<>"","Bayu Rizki Alfarizi","")
A30: =IF($B30<>"",ROW()-4,"") | H30: =IF($B30<>"","Bayu Rizki Alfarizi","")
A31: =IF($B31<>"",ROW()-4,"") | H31: =IF($B31<>"","Bayu Rizki Alfarizi","") | J31: Sabtu
A32: =IF($B32<>"",ROW()-4,"") | H32: =IF($B32<>"","Bayu Rizki Alfarizi","")
A33: =IF($B33<>"",ROW()-4,"") | H33: =IF($B33<>"","Bayu Rizki Alfarizi","")
A34: =IF($B34<>"",ROW()-4,"") | H34: =IF($B34<>"","Bayu Rizki Alfarizi","")
A35: =IF($B35<>"",ROW()-4,"") | H35: =IF($B35<>"","Bayu Rizki Alfarizi","")
A36: =IF($B36<>"",ROW()-4,"") | H36: =IF($B36<>"","Bayu Rizki Alfarizi","")
A37: =IF($B37<>"",ROW()-4,"") | H37: =IF($B37<>"","Bayu Rizki Alfarizi","")
A38: =IF($B38<>"",ROW()-4,"") | H38: =IF($B38<>"","Bayu Rizki Alfarizi","")
A39: =IF($B39<>"",ROW()-4,"") | H39: =IF($B39<>"","Bayu Rizki Alfarizi","")
A40: =IF($B40<>"",ROW()-4,"") | H40: =IF($B40<>"","Bayu Rizki Alfarizi","")
...

Sheet Chandanie Nely Agustin
A1: TWENTY SWIM - LEVEL SISWA & JADWAL LATIHAN (BANDUNG)
A2: Pelatih: Chandanie Nely Agustin | D2: Terisi: | E2: =COUNTA($B$5:$B$54) | F2: siswa
A3: Isi kolom putih. Kolom berwarna = dropdown, tinggal pilih. No & Coach terisi otomatis.
A4: No | B4: Nama Siswa | C4: Program/Kelas | D4: Level Saat Ini | E4: Status | F4: Risiko | G4: Sosialisasi Keselamatan ke Ortu | H4: Coach | J4: JADWAL LATIHAN (Senin-Jumat 5 baris, Sabtu-Minggu 10 baris)
A5: =IF($B5<>"",ROW()-4,"") | B5: Ralinka shayna alsavana lubis | D5: Preschool I | E5: Standalone | H5: =IF($B5<>"","Chandanie Nely Agustin","") | J5: Hari | K5: Jam | L5: Nama Siswa | M5: Lokasi (wilayah) | N5: Kolam
A6: =IF($B6<>"",ROW()-4,"") | B6: Arunika Hara Patanjala | D6: Aquatike III | E6: Standalone | H6: =IF($B6<>"","Chandanie Nely Agustin","") | J6: Senin
A7: =IF($B7<>"",ROW()-4,"") | B7: Kaif Rasyid Afkarian | D7: Beginner I | E7: Standalone | H7: =IF($B7<>"","Chandanie Nely Agustin","")
A8: =IF($B8<>"",ROW()-4,"") | B8: Hafidzah Kifah | D8: Intermediate I | E8: Standalone | H8: =IF($B8<>"","Chandanie Nely Agustin","")
A9: =IF($B9<>"",ROW()-4,"") | B9: Kalea | D9: Aquatike I | E9: Standalone | H9: =IF($B9<>"","Chandanie Nely Agustin","")
A10: =IF($B10<>"",ROW()-4,"") | B10: Nayyara Almahyra mecca | D10: Preschool I | E10: Standalone | H10: =IF($B10<>"","Chandanie Nely Agustin","")
A11: =IF($B11<>"",ROW()-4,"") | B11: Fabian | D11: Beginner I | E11: Standalone | H11: =IF($B11<>"","Chandanie Nely Agustin","") | J11: Selasa
A12: =IF($B12<>"",ROW()-4,"") | B12: Maryam dita adya | D12: Preschool I | E12: Standalone | H12: =IF($B12<>"","Chandanie Nely Agustin","")
A13: =IF($B13<>"",ROW()-4,"") | B13: Kaisya | D13: Beginner I | E13: Standalone | H13: =IF($B13<>"","Chandanie Nely Agustin","")
A14: =IF($B14<>"",ROW()-4,"") | B14: Diandra khairunisa | D14: Beginner I | E14: Standalone | H14: =IF($B14<>"","Chandanie Nely Agustin","")
A15: =IF($B15<>"",ROW()-4,"") | B15: Sebumi nan damai | D15: Preschool I | E15: Standalone | H15: =IF($B15<>"","Chandanie Nely Agustin","")
A16: =IF($B16<>"",ROW()-4,"") | B16: Egriveda Enzilma | D16: Preschool I | E16: Standalone | H16: =IF($B16<>"","Chandanie Nely Agustin","") | J16: Rabu
A17: =IF($B17<>"",ROW()-4,"") | B17: Saabira | D17: Preschool I | E17: Standalone | H17: =IF($B17<>"","Chandanie Nely Agustin","")
A18: =IF($B18<>"",ROW()-4,"") | B18: Azka | D18: Aquatike I | E18: PA | H18: =IF($B18<>"","Chandanie Nely Agustin","")
A19: =IF($B19<>"",ROW()-4,"") | B19: Gibraneda Naratas Jagat | D19: Aquatike I | E19: PA | H19: =IF($B19<>"","Chandanie Nely Agustin","")
A20: =IF($B20<>"",ROW()-4,"") | B20: Naira Azalia Maharani | D20: Preschool I | E20: Standalone | H20: =IF($B20<>"","Chandanie Nely Agustin","")
A21: =IF($B21<>"",ROW()-4,"") | B21: Alesha Putri Sekar Pandan | D21: Aquatike I | E21: Standalone | H21: =IF($B21<>"","Chandanie Nely Agustin","") | J21: Kamis
A22: =IF($B22<>"",ROW()-4,"") | B22: Athiyah Nurmaulida Alina | D22: Preschool I | E22: Standalone | H22: =IF($B22<>"","Chandanie Nely Agustin","")
A23: =IF($B23<>"",ROW()-4,"") | B23: Aira | D23: Preschool I | E23: Standalone | H23: =IF($B23<>"","Chandanie Nely Agustin","")
A24: =IF($B24<>"",ROW()-4,"") | B24: Shaima Adawizi Shanum | D24: Preschool I | E24: Standalone | H24: =IF($B24<>"","Chandanie Nely Agustin","")
A25: =IF($B25<>"",ROW()-4,"") | B25: Kendis Keinara Anrifa | D25: Intermediate I | E25: Standalone | H25: =IF($B25<>"","Chandanie Nely Agustin","")
A26: =IF($B26<>"",ROW()-4,"") | B26: Hayyin Sabrina Satriadama | D26: Preschool I | E26: Standalone | H26: =IF($B26<>"","Chandanie Nely Agustin","") | J26: Jumat
A27: =IF($B27<>"",ROW()-4,"") | B27: Lavanya | D27: Beginner I | E27: Standalone | H27: =IF($B27<>"","Chandanie Nely Agustin","")
A28: =IF($B28<>"",ROW()-4,"") | B28: Naomi | D28: Preschool I | E28: Standalone | H28: =IF($B28<>"","Chandanie Nely Agustin","")
A29: =IF($B29<>"",ROW()-4,"") | B29: nichirin | D29: Aquatike I | H29: =IF($B29<>"","Chandanie Nely Agustin","")
A30: =IF($B30<>"",ROW()-4,"") | B30: sabila | D30: Aquatike I | H30: =IF($B30<>"","Chandanie Nely Agustin","")
A31: =IF($B31<>"",ROW()-4,"") | B31: nara | D31: Aquatike I | H31: =IF($B31<>"","Chandanie Nely Agustin","") | J31: Sabtu
A32: =IF($B32<>"",ROW()-4,"") | H32: =IF($B32<>"","Chandanie Nely Agustin","")
A33: =IF($B33<>"",ROW()-4,"") | H33: =IF($B33<>"","Chandanie Nely Agustin","")
A34: =IF($B34<>"",ROW()-4,"") | H34: =IF($B34<>"","Chandanie Nely Agustin","")
A35: =IF($B35<>"",ROW()-4,"") | H35: =IF($B35<>"","Chandanie Nely Agustin","")
A36: =IF($B36<>"",ROW()-4,"") | H36: =IF($B36<>"","Chandanie Nely Agustin","")
A37: =IF($B37<>"",ROW()-4,"") | H37: =IF($B37<>"","Chandanie Nely Agustin","")
A38: =IF($B38<>"",ROW()-4,"") | H38: =IF($B38<>"","Chandanie Nely Agustin","")
A39: =IF($B39<>"",ROW()-4,"") | H39: =IF($B39<>"","Chandanie Nely Agustin","")
A40: =IF($B40<>"",ROW()-4,"") | H40: =IF($B40<>"","Chandanie Nely Agustin","")
...

Sheet Dida Zein Risty
A1: TWENTY SWIM - LEVEL SISWA & JADWAL LATIHAN (BANDUNG)
A2: Pelatih: Dida Zein Risty | D2: Terisi: | E2: =COUNTA($B$5:$B$54) | F2: siswa
A3: Isi kolom putih. Kolom berwarna = dropdown, tinggal pilih. No & Coach terisi otomatis.
A4: No | B4: Nama Siswa | C4: Program/Kelas | D4: Level Saat Ini | E4: Status | F4: Risiko | G4: Sosialisasi Keselamatan ke Ortu | H4: Coach | J4: JADWAL LATIHAN (Senin-Jumat 5 baris, Sabtu-Minggu 10 baris)
A5: =IF($B5<>"",ROW()-4,"") | B5: Syakira Khansa Iskandar | D5: Swim Team Prep | E5: Standalone | H5: =IF($B5<>"","Dida Zein Risty","") | J5: Hari | K5: Jam | L5: Nama Siswa | M5: Lokasi (wilayah) | N5: Kolam
A6: =IF($B6<>"",ROW()-4,"") | B6: Syakila Nesha Iskandar | D6: Swim Team Prep | E6: Standalone | H6: =IF($B6<>"","Dida Zein Risty","") | J6: Senin
A7: =IF($B7<>"",ROW()-4,"") | B7: Alma Yuki Zaina | D7: Beginner III | E7: PA | H7: =IF($B7<>"","Dida Zein Risty","")
A8: =IF($B8<>"",ROW()-4,"") | B8: Beyza Ruchika Kaureen | D8: Aquatike I | E8: PA | H8: =IF($B8<>"","Dida Zein Risty","")
A9: =IF($B9<>"",ROW()-4,"") | B9: Aurora Shabira Hidayatri | D9: Preschool I | E9: PA | H9: =IF($B9<>"","Dida Zein Risty","")
A10: =IF($B10<>"",ROW()-4,"") | B10: Aretha Zayyana Putri A | D10: Beginner I | E10: PA | H10: =IF($B10<>"","Dida Zein Risty","")
A11: =IF($B11<>"",ROW()-4,"") | B11: Kayyisa Kirana Yusuf | D11: Beginner I | E11: PA | H11: =IF($B11<>"","Dida Zein Risty","") | J11: Selasa
A12: =IF($B12<>"",ROW()-4,"") | B12: Fathin Ramadhaniah Azhari | D12: Beginner I | E12: PA | H12: =IF($B12<>"","Dida Zein Risty","")
A13: =IF($B13<>"",ROW()-4,"") | B13: Fadhlan Ahmad Ramadhan | D13: Swim Team Prep | E13: Standalone | H13: =IF($B13<>"","Dida Zein Risty","")
A14: =IF($B14<>"",ROW()-4,"") | B14: Dzakirul Abyan Al-Hazim | D14: Swim Team Prep | E14: Standalone | H14: =IF($B14<>"","Dida Zein Risty","")
A15: =IF($B15<>"",ROW()-4,"") | B15: Almatiara Syifaa Firmansyah | D15: Preschool I | E15: PA | H15: =IF($B15<>"","Dida Zein Risty","")
A16: =IF($B16<>"",ROW()-4,"") | B16: Dyra Arummy | D16: Beginner III | E16: PA | H16: =IF($B16<>"","Dida Zein Risty","") | J16: Rabu
A17: =IF($B17<>"",ROW()-4,"") | B17: Marsha Zebina Richsan | D17: Beginner III | E17: PA | H17: =IF($B17<>"","Dida Zein Risty","")
A18: =IF($B18<>"",ROW()-4,"") | B18: Nesya Maheswari | D18: Beginner I | E18: PA | H18: =IF($B18<>"","Dida Zein Risty","")
A19: =IF($B19<>"",ROW()-4,"") | B19: Aleena Sadeeqa Maheooba | D19: Beginner I | E19: PA | H19: =IF($B19<>"","Dida Zein Risty","")
A20: =IF($B20<>"",ROW()-4,"") | B20: Sharna saqeenarava ananta | D20: Beginner I | E20: PA | H20: =IF($B20<>"","Dida Zein Risty","")
A21: =IF($B21<>"",ROW()-4,"") | H21: =IF($B21<>"","Dida Zein Risty","") | J21: Kamis
A22: =IF($B22<>"",ROW()-4,"") | H22: =IF($B22<>"","Dida Zein Risty","")
A23: =IF($B23<>"",ROW()-4,"") | H23: =IF($B23<>"","Dida Zein Risty","")
A24: =IF($B24<>"",ROW()-4,"") | H24: =IF($B24<>"","Dida Zein Risty","")
A25: =IF($B25<>"",ROW()-4,"") | H25: =IF($B25<>"","Dida Zein Risty","")
A26: =IF($B26<>"",ROW()-4,"") | H26: =IF($B26<>"","Dida Zein Risty","") | J26: Jumat
A27: =IF($B27<>"",ROW()-4,"") | H27: =IF($B27<>"","Dida Zein Risty","")
A28: =IF($B28<>"",ROW()-4,"") | H28: =IF($B28<>"","Dida Zein Risty","")
A29: =IF($B29<>"",ROW()-4,"") | H29: =IF($B29<>"","Dida Zein Risty","")
A30: =IF($B30<>"",ROW()-4,"") | H30: =IF($B30<>"","Dida Zein Risty","")
A31: =IF($B31<>"",ROW()-4,"") | H31: =IF($B31<>"","Dida Zein Risty","") | J31: Sabtu
A32: =IF($B32<>"",ROW()-4,"") | H32: =IF($B32<>"","Dida Zein Risty","")
A33: =IF($B33<>"",ROW()-4,"") | H33: =IF($B33<>"","Dida Zein Risty","")
A34: =IF($B34<>"",ROW()-4,"") | H34: =IF($B34<>"","Dida Zein Risty","")
A35: =IF($B35<>"",ROW()-4,"") | H35: =IF($B35<>"","Dida Zein Risty","")
A36: =IF($B36<>"",ROW()-4,"") | H36: =IF($B36<>"","Dida Zein Risty","")
A37: =IF($B37<>"",ROW()-4,"") | H37: =IF($B37<>"","Dida Zein Risty","")
A38: =IF($B38<>"",ROW()-4,"") | H38: =IF($B38<>"","Dida Zein Risty","")
A39: =IF($B39<>"",ROW()-4,"") | H39: =IF($B39<>"","Dida Zein Risty","")
A40: =IF($B40<>"",ROW()-4,"") | H40: =IF($B40<>"","Dida Zein Risty","")
...

Sheet Fadil Rijatul Haq
A1: TWENTY SWIM - LEVEL SISWA & JADWAL LATIHAN (BANDUNG)
A2: Pelatih: Fadil Rijatul Haq | D2: Terisi: | E2: =COUNTA($B$5:$B$54) | F2: siswa
A3: Isi kolom putih. Kolom berwarna = dropdown, tinggal pilih. No & Coach terisi otomatis.
A4: No | B4: Nama Siswa | C4: Program/Kelas | D4: Level Saat Ini | E4: Status | F4: Risiko | G4: Sosialisasi Keselamatan ke Ortu | H4: Coach | J4: JADWAL LATIHAN (Senin-Jumat 5 baris, Sabtu-Minggu 10 baris)
A5: =IF($B5<>"",ROW()-4,"") | B5: Muhammad Baraja | D5: Aquatike I | E5: Standalone | H5: =IF($B5<>"","Fadil Rijatul Haq","") | J5: Hari | K5: Jam | L5: Nama Siswa | M5: Lokasi (wilayah) | N5: Kolam
A6: =IF($B6<>"",ROW()-4,"") | B6: Muammar Maliqi Hidayat | D6: Aquatike I | E6: Standalone | H6: =IF($B6<>"","Fadil Rijatul Haq","") | J6: Senin
A7: =IF($B7<>"",ROW()-4,"") | B7: Emirza Abyan Rusman | D7: Preschool I | E7: Standalone | H7: =IF($B7<>"","Fadil Rijatul Haq","")
A8: =IF($B8<>"",ROW()-4,"") | B8: Alfatih Sakti Marantika | D8: Beginner II | E8: Standalone | H8: =IF($B8<>"","Fadil Rijatul Haq","")
A9: =IF($B9<>"",ROW()-4,"") | B9: Yehezkiel Valentino Simarmata | D9: Preschool I | E9: Standalone | H9: =IF($B9<>"","Fadil Rijatul Haq","")
A10: =IF($B10<>"",ROW()-4,"") | B10: Muhamad Avatar Saputra | D10: Beginner I | E10: Standalone | H10: =IF($B10<>"","Fadil Rijatul Haq","")
A11: =IF($B11<>"",ROW()-4,"") | B11: Nevan Fabian Ar Rayan | D11: Beginner I | E11: Standalone | H11: =IF($B11<>"","Fadil Rijatul Haq","") | J11: Selasa
A12: =IF($B12<>"",ROW()-4,"") | B12: Sabam Sean Simarmata | D12: Beginner I | E12: Standalone | H12: =IF($B12<>"","Fadil Rijatul Haq","")
A13: =IF($B13<>"",ROW()-4,"") | B13: Josaphat Dewananda Surya | D13: Preschool I | E13: Standalone | H13: =IF($B13<>"","Fadil Rijatul Haq","")
A14: =IF($B14<>"",ROW()-4,"") | B14: Leonard Gavriel Marcello | D14: Preschool I | E14: Standalone | H14: =IF($B14<>"","Fadil Rijatul Haq","")
A15: =IF($B15<>"",ROW()-4,"") | B15: Adnan Sakhi Nugraha | D15: Preschool I | E15: Standalone | H15: =IF($B15<>"","Fadil Rijatul Haq","")
A16: =IF($B16<>"",ROW()-4,"") | B16: Nathanliam Gavriel Napitupulu | D16: Intermediate II | E16: Standalone | H16: =IF($B16<>"","Fadil Rijatul Haq","") | J16: Rabu
A17: =IF($B17<>"",ROW()-4,"") | B17: Athafariz Haikal Rafif | D17: Beginner I | E17: Standalone | H17: =IF($B17<>"","Fadil Rijatul Haq","")
A18: =IF($B18<>"",ROW()-4,"") | H18: =IF($B18<>"","Fadil Rijatul Haq","")
A19: =IF($B19<>"",ROW()-4,"") | H19: =IF($B19<>"","Fadil Rijatul Haq","")
A20: =IF($B20<>"",ROW()-4,"") | H20: =IF($B20<>"","Fadil Rijatul Haq","")
A21: =IF($B21<>"",ROW()-4,"") | H21: =IF($B21<>"","Fadil Rijatul Haq","") | J21: Kamis
A22: =IF($B22<>"",ROW()-4,"") | H22: =IF($B22<>"","Fadil Rijatul Haq","")
A23: =IF($B23<>"",ROW()-4,"") | H23: =IF($B23<>"","Fadil Rijatul Haq","")
A24: =IF($B24<>"",ROW()-4,"") | H24: =IF($B24<>"","Fadil Rijatul Haq","")
A25: =IF($B25<>"",ROW()-4,"") | H25: =IF($B25<>"","Fadil Rijatul Haq","")
A26: =IF($B26<>"",ROW()-4,"") | H26: =IF($B26<>"","Fadil Rijatul Haq","") | J26: Jumat
A27: =IF($B27<>"",ROW()-4,"") | H27: =IF($B27<>"","Fadil Rijatul Haq","")
A28: =IF($B28<>"",ROW()-4,"") | H28: =IF($B28<>"","Fadil Rijatul Haq","")
A29: =IF($B29<>"",ROW()-4,"") | H29: =IF($B29<>"","Fadil Rijatul Haq","")
A30: =IF($B30<>"",ROW()-4,"") | H30: =IF($B30<>"","Fadil Rijatul Haq","")
A31: =IF($B31<>"",ROW()-4,"") | H31: =IF($B31<>"","Fadil Rijatul Haq","") | J31: Sabtu
A32: =IF($B32<>"",ROW()-4,"") | H32: =IF($B32<>"","Fadil Rijatul Haq","")
A33: =IF($B33<>"",ROW()-4,"") | H33: =IF($B33<>"","Fadil Rijatul Haq","")
A34: =IF($B34<>"",ROW()-4,"") | H34: =IF($B34<>"","Fadil Rijatul Haq","")
A35: =IF($B35<>"",ROW()-4,"") | H35: =IF($B35<>"","Fadil Rijatul Haq","")
A36: =IF($B36<>"",ROW()-4,"") | H36: =IF($B36<>"","Fadil Rijatul Haq","")
A37: =IF($B37<>"",ROW()-4,"") | H37: =IF($B37<>"","Fadil Rijatul Haq","")
A38: =IF($B38<>"",ROW()-4,"") | H38: =IF($B38<>"","Fadil Rijatul Haq","")
A39: =IF($B39<>"",ROW()-4,"") | H39: =IF($B39<>"","Fadil Rijatul Haq","")
A40: =IF($B40<>"",ROW()-4,"") | H40: =IF($B40<>"","Fadil Rijatul Haq","")
...

Sheet Faega Fitriani Dwi Putri
A1: TWENTY SWIM - LEVEL SISWA & JADWAL LATIHAN (BANDUNG)
A2: Pelatih: Faega Fitriani Dwi Putri | D2: Terisi: | E2: =COUNTA($B$5:$B$54) | F2: siswa
A3: Isi kolom putih. Kolom berwarna = dropdown, tinggal pilih. No & Coach terisi otomatis.
A4: No | B4: Nama Siswa | C4: Program/Kelas | D4: Level Saat Ini | E4: Status | F4: Risiko | G4: Sosialisasi Keselamatan ke Ortu | H4: Coach | J4: JADWAL LATIHAN (Senin-Jumat 5 baris, Sabtu-Minggu 10 baris)
A5: =IF($B5<>"",ROW()-4,"") | B5: Ahza Rumaisa Prawesty | D5: Preschool II | E5: PA | H5: =IF($B5<>"","Faega Fitriani Dwi Putri","") | J5: Hari | K5: Jam | L5: Nama Siswa | M5: Lokasi (wilayah) | N5: Kolam
A6: =IF($B6<>"",ROW()-4,"") | B6: Klarissa Syamei Pahlani | D6: Preschool I | E6: PA | H6: =IF($B6<>"","Faega Fitriani Dwi Putri","") | J6: Senin
A7: =IF($B7<>"",ROW()-4,"") | B7: Elvaretta Karina Noristian | D7: Intermediate II | E7: Standalone | H7: =IF($B7<>"","Faega Fitriani Dwi Putri","")
A8: =IF($B8<>"",ROW()-4,"") | B8: Aysha Adzkiya | D8: Aquatike II | E8: PA | H8: =IF($B8<>"","Faega Fitriani Dwi Putri","")
A9: =IF($B9<>"",ROW()-4,"") | B9: Alula Khaliqa Dzahim | D9: Advanced I | E9: Standalone | H9: =IF($B9<>"","Faega Fitriani Dwi Putri","")
A10: =IF($B10<>"",ROW()-4,"") | B10: Manggala Nabil Aqla | D10: Intermediate I | E10: PA | H10: =IF($B10<>"","Faega Fitriani Dwi Putri","")
A11: =IF($B11<>"",ROW()-4,"") | B11: Ellmir Khalil Muazzam | D11: Preschool I | E11: PA | H11: =IF($B11<>"","Faega Fitriani Dwi Putri","") | J11: Selasa
A12: =IF($B12<>"",ROW()-4,"") | B12: Raya Kaira Mujtaba | D12: Beginner I | E12: PA | H12: =IF($B12<>"","Faega Fitriani Dwi Putri","")
A13: =IF($B13<>"",ROW()-4,"") | B13: Sarah Diandra Kirana | D13: Intermediate II | E13: Standalone | H13: =IF($B13<>"","Faega Fitriani Dwi Putri","")
A14: =IF($B14<>"",ROW()-4,"") | B14: Tranquilia Syifa Handriana | D14: Advanced II | E14: Standalone | H14: =IF($B14<>"","Faega Fitriani Dwi Putri","")
A15: =IF($B15<>"",ROW()-4,"") | B15: Syarifah Muscarida Handriana | D15: Beginner II | E15: PA | H15: =IF($B15<>"","Faega Fitriani Dwi Putri","")
A16: =IF($B16<>"",ROW()-4,"") | B16: Abdillah Muhammad Salahuddin Handria | D16: Beginner I | E16: PA | H16: =IF($B16<>"","Faega Fitriani Dwi Putri","") | J16: Rabu
A17: =IF($B17<>"",ROW()-4,"") | B17: Muhammad Nouman Khalid Handria | D17: Aquatike I | E17: PA | H17: =IF($B17<>"","Faega Fitriani Dwi Putri","")
A18: =IF($B18<>"",ROW()-4,"") | B18: Btari Alika Nazma W | C18: Baby Swim | D18: Baby Swim II | E18: PA | H18: =IF($B18<>"","Faega Fitriani Dwi Putri","")
A19: =IF($B19<>"",ROW()-4,"") | B19: Sheza Syera Kailazea | D19: Preschool I | E19: PA | H19: =IF($B19<>"","Faega Fitriani Dwi Putri","")
A20: =IF($B20<>"",ROW()-4,"") | B20: Afifah Nasha Hamidah | D20: Beginner I | E20: PA | H20: =IF($B20<>"","Faega Fitriani Dwi Putri","")
A21: =IF($B21<>"",ROW()-4,"") | H21: =IF($B21<>"","Faega Fitriani Dwi Putri","") | J21: Kamis
A22: =IF($B22<>"",ROW()-4,"") | H22: =IF($B22<>"","Faega Fitriani Dwi Putri","")
A23: =IF($B23<>"",ROW()-4,"") | H23: =IF($B23<>"","Faega Fitriani Dwi Putri","")
A24: =IF($B24<>"",ROW()-4,"") | H24: =IF($B24<>"","Faega Fitriani Dwi Putri","")
A25: =IF($B25<>"",ROW()-4,"") | H25: =IF($B25<>"","Faega Fitriani Dwi Putri","")
A26: =IF($B26<>"",ROW()-4,"") | H26: =IF($B26<>"","Faega Fitriani Dwi Putri","") | J26: Jumat
A27: =IF($B27<>"",ROW()-4,"") | H27: =IF($B27<>"","Faega Fitriani Dwi Putri","")
A28: =IF($B28<>"",ROW()-4,"") | H28: =IF($B28<>"","Faega Fitriani Dwi Putri","")
A29: =IF($B29<>"",ROW()-4,"") | H29: =IF($B29<>"","Faega Fitriani Dwi Putri","")
A30: =IF($B30<>"",ROW()-4,"") | H30: =IF($B30<>"","Faega Fitriani Dwi Putri","")
A31: =IF($B31<>"",ROW()-4,"") | H31: =IF($B31<>"","Faega Fitriani Dwi Putri","") | J31: Sabtu
A32: =IF($B32<>"",ROW()-4,"") | H32: =IF($B32<>"","Faega Fitriani Dwi Putri","")
A33: =IF($B33<>"",ROW()-4,"") | H33: =IF($B33<>"","Faega Fitriani Dwi Putri","")
A34: =IF($B34<>"",ROW()-4,"") | H34: =IF($B34<>"","Faega Fitriani Dwi Putri","")
A35: =IF($B35<>"",ROW()-4,"") | H35: =IF($B35<>"","Faega Fitriani Dwi Putri","")
A36: =IF($B36<>"",ROW()-4,"") | H36: =IF($B36<>"","Faega Fitriani Dwi Putri","")
A37: =IF($B37<>"",ROW()-4,"") | H37: =IF($B37<>"","Faega Fitriani Dwi Putri","")
A38: =IF($B38<>"",ROW()-4,"") | H38: =IF($B38<>"","Faega Fitriani Dwi Putri","")
A39: =IF($B39<>"",ROW()-4,"") | H39: =IF($B39<>"","Faega Fitriani Dwi Putri","")
A40: =IF($B40<>"",ROW()-4,"") | H40: =IF($B40<>"","Faega Fitriani Dwi Putri","")
...

Sheet Fajri Rizki Robbani
A1: TWENTY SWIM - LEVEL SISWA & JADWAL LATIHAN (BANDUNG)
A2: Pelatih: Fajri Rizki Robbani | D2: Terisi: | E2: =COUNTA($B$5:$B$54) | F2: siswa
A3: Isi kolom putih. Kolom berwarna = dropdown, tinggal pilih. No & Coach terisi otomatis.
A4: No | B4: Nama Siswa | C4: Program/Kelas | D4: Level Saat Ini | E4: Status | F4: Risiko | G4: Sosialisasi Keselamatan ke Ortu | H4: Coach | J4: JADWAL LATIHAN (Senin-Jumat 5 baris, Sabtu-Minggu 10 baris)
A5: =IF($B5<>"",ROW()-4,"") | B5: Daffa | D5: Beginner I | E5: PA | H5: =IF($B5<>"","Fajri Rizki Robbani","") | J5: Hari | K5: Jam | L5: Nama Siswa | M5: Lokasi (wilayah) | N5: Kolam
A6: =IF($B6<>"",ROW()-4,"") | B6: Athala Rayen | D6: Beginner II | E6: PA | H6: =IF($B6<>"","Fajri Rizki Robbani","") | J6: Senin
A7: =IF($B7<>"",ROW()-4,"") | B7: Aufa | D7: Intermediate II | E7: Standalone | H7: =IF($B7<>"","Fajri Rizki Robbani","")
A8: =IF($B8<>"",ROW()-4,"") | B8: Genta | D8: Intermediate I | E8: PA | H8: =IF($B8<>"","Fajri Rizki Robbani","")
A9: =IF($B9<>"",ROW()-4,"") | B9: Rizqi | D9: Beginner II | E9: PA | H9: =IF($B9<>"","Fajri Rizki Robbani","")
A10: =IF($B10<>"",ROW()-4,"") | B10: Aizan | D10: Preschool II | E10: PA | H10: =IF($B10<>"","Fajri Rizki Robbani","")
A11: =IF($B11<>"",ROW()-4,"") | B11: Varrel | D11: Intermediate I | E11: Standalone | H11: =IF($B11<>"","Fajri Rizki Robbani","") | J11: Selasa
A12: =IF($B12<>"",ROW()-4,"") | B12: Athalla | D12: Beginner III | E12: PA | H12: =IF($B12<>"","Fajri Rizki Robbani","")
A13: =IF($B13<>"",ROW()-4,"") | B13: Arazka | D13: Beginner III | E13: PA | H13: =IF($B13<>"","Fajri Rizki Robbani","")
A14: =IF($B14<>"",ROW()-4,"") | B14: Arsene | D14: Beginner II | E14: PA | H14: =IF($B14<>"","Fajri Rizki Robbani","")
A15: =IF($B15<>"",ROW()-4,"") | B15: Abidzar | D15: Beginner II | E15: PA | H15: =IF($B15<>"","Fajri Rizki Robbani","")
A16: =IF($B16<>"",ROW()-4,"") | B16: Hamzah | D16: Aquatike I | E16: PA | H16: =IF($B16<>"","Fajri Rizki Robbani","") | J16: Rabu
A17: =IF($B17<>"",ROW()-4,"") | H17: =IF($B17<>"","Fajri Rizki Robbani","")
A18: =IF($B18<>"",ROW()-4,"") | H18: =IF($B18<>"","Fajri Rizki Robbani","")
A19: =IF($B19<>"",ROW()-4,"") | H19: =IF($B19<>"","Fajri Rizki Robbani","")
A20: =IF($B20<>"",ROW()-4,"") | H20: =IF($B20<>"","Fajri Rizki Robbani","")
A21: =IF($B21<>"",ROW()-4,"") | H21: =IF($B21<>"","Fajri Rizki Robbani","") | J21: Kamis
A22: =IF($B22<>"",ROW()-4,"") | H22: =IF($B22<>"","Fajri Rizki Robbani","")
A23: =IF($B23<>"",ROW()-4,"") | H23: =IF($B23<>"","Fajri Rizki Robbani","")
A24: =IF($B24<>"",ROW()-4,"") | H24: =IF($B24<>"","Fajri Rizki Robbani","")
A25: =IF($B25<>"",ROW()-4,"") | H25: =IF($B25<>"","Fajri Rizki Robbani","")
A26: =IF($B26<>"",ROW()-4,"") | H26: =IF($B26<>"","Fajri Rizki Robbani","") | J26: Jumat
A27: =IF($B27<>"",ROW()-4,"") | H27: =IF($B27<>"","Fajri Rizki Robbani","")
A28: =IF($B28<>"",ROW()-4,"") | H28: =IF($B28<>"","Fajri Rizki Robbani","")
A29: =IF($B29<>"",ROW()-4,"") | H29: =IF($B29<>"","Fajri Rizki Robbani","")
A30: =IF($B30<>"",ROW()-4,"") | H30: =IF($B30<>"","Fajri Rizki Robbani","")
A31: =IF($B31<>"",ROW()-4,"") | H31: =IF($B31<>"","Fajri Rizki Robbani","") | J31: Sabtu
A32: =IF($B32<>"",ROW()-4,"") | H32: =IF($B32<>"","Fajri Rizki Robbani","")
A33: =IF($B33<>"",ROW()-4,"") | H33: =IF($B33<>"","Fajri Rizki Robbani","")
A34: =IF($B34<>"",ROW()-4,"") | H34: =IF($B34<>"","Fajri Rizki Robbani","")
A35: =IF($B35<>"",ROW()-4,"") | H35: =IF($B35<>"","Fajri Rizki Robbani","")
A36: =IF($B36<>"",ROW()-4,"") | H36: =IF($B36<>"","Fajri Rizki Robbani","")
A37: =IF($B37<>"",ROW()-4,"") | H37: =IF($B37<>"","Fajri Rizki Robbani","")
A38: =IF($B38<>"",ROW()-4,"") | H38: =IF($B38<>"","Fajri Rizki Robbani","")
A39: =IF($B39<>"",ROW()-4,"") | H39: =IF($B39<>"","Fajri Rizki Robbani","")
A40: =IF($B40<>"",ROW()-4,"") | H40: =IF($B40<>"","Fajri Rizki Robbani","")
...

Sheet Fakhri Safrudin Sopandi
A1: TWENTY SWIM - LEVEL SISWA & JADWAL LATIHAN (BANDUNG)
A2: Pelatih: Fakhri Safrudin Sopandi | D2: Terisi: | E2: =COUNTA($B$5:$B$54) | F2: siswa
A3: Isi kolom putih. Kolom berwarna = dropdown, tinggal pilih. No & Coach terisi otomatis.
A4: No | B4: Nama Siswa | C4: Program/Kelas | D4: Level Saat Ini | E4: Status | F4: Risiko | G4: Sosialisasi Keselamatan ke Ortu | H4: Coach | J4: JADWAL LATIHAN (Senin-Jumat 5 baris, Sabtu-Minggu 10 baris)
A5: =IF($B5<>"",ROW()-4,"") | B5: Rumi Aldibara Noor | D5: Advanced I | E5: Standalone | H5: =IF($B5<>"","Fakhri Safrudin Sopandi","") | J5: Hari | K5: Jam | L5: Nama Siswa | M5: Lokasi (wilayah) | N5: Kolam
A6: =IF($B6<>"",ROW()-4,"") | B6: Samuel Moto Natama | D6: Beginner III | E6: Standalone | H6: =IF($B6<>"","Fakhri Safrudin Sopandi","") | J6: Senin
A7: =IF($B7<>"",ROW()-4,"") | B7: Mathias lasdo Artana | D7: Beginner I | E7: Standalone | H7: =IF($B7<>"","Fakhri Safrudin Sopandi","")
A8: =IF($B8<>"",ROW()-4,"") | B8: Alshan Danendra Gafa | D8: Aquatike I | E8: Standalone | H8: =IF($B8<>"","Fakhri Safrudin Sopandi","")
A9: =IF($B9<>"",ROW()-4,"") | B9: Muhammad Aufa Ghaisani | D9: Beginner I | E9: Standalone | H9: =IF($B9<>"","Fakhri Safrudin Sopandi","")
A10: =IF($B10<>"",ROW()-4,"") | B10: Fauzan Kareemzafran | D10: Beginner I | E10: Standalone | H10: =IF($B10<>"","Fakhri Safrudin Sopandi","")
A11: =IF($B11<>"",ROW()-4,"") | B11: Fauzan Asfa | D11: Swim Team Prep | E11: Standalone | H11: =IF($B11<>"","Fakhri Safrudin Sopandi","") | J11: Selasa
A12: =IF($B12<>"",ROW()-4,"") | B12: Hasbi Assidqi | D12: Beginner I | E12: Standalone | H12: =IF($B12<>"","Fakhri Safrudin Sopandi","")
A13: =IF($B13<>"",ROW()-4,"") | B13: Devandra Omar | C13: Baby Swim | D13: Baby Swim I | E13: PA | H13: =IF($B13<>"","Fakhri Safrudin Sopandi","")
A14: =IF($B14<>"",ROW()-4,"") | B14: Muhammad Arkan | D14: Beginner I | E14: Standalone | H14: =IF($B14<>"","Fakhri Safrudin Sopandi","")
A15: =IF($B15<>"",ROW()-4,"") | B15: Muhammad Althaf | D15: Beginner I | E15: Standalone | H15: =IF($B15<>"","Fakhri Safrudin Sopandi","")
A16: =IF($B16<>"",ROW()-4,"") | H16: =IF($B16<>"","Fakhri Safrudin Sopandi","") | J16: Rabu
A17: =IF($B17<>"",ROW()-4,"") | H17: =IF($B17<>"","Fakhri Safrudin Sopandi","")
A18: =IF($B18<>"",ROW()-4,"") | H18: =IF($B18<>"","Fakhri Safrudin Sopandi","")
A19: =IF($B19<>"",ROW()-4,"") | H19: =IF($B19<>"","Fakhri Safrudin Sopandi","")
A20: =IF($B20<>"",ROW()-4,"") | H20: =IF($B20<>"","Fakhri Safrudin Sopandi","")
A21: =IF($B21<>"",ROW()-4,"") | H21: =IF($B21<>"","Fakhri Safrudin Sopandi","") | J21: Kamis
A22: =IF($B22<>"",ROW()-4,"") | H22: =IF($B22<>"","Fakhri Safrudin Sopandi","")
A23: =IF($B23<>"",ROW()-4,"") | H23: =IF($B23<>"","Fakhri Safrudin Sopandi","")
A24: =IF($B24<>"",ROW()-4,"") | H24: =IF($B24<>"","Fakhri Safrudin Sopandi","")
A25: =IF($B25<>"",ROW()-4,"") | H25: =IF($B25<>"","Fakhri Safrudin Sopandi","")
A26: =IF($B26<>"",ROW()-4,"") | H26: =IF($B26<>"","Fakhri Safrudin Sopandi","") | J26: Jumat
A27: =IF($B27<>"",ROW()-4,"") | H27: =IF($B27<>"","Fakhri Safrudin Sopandi","")
A28: =IF($B28<>"",ROW()-4,"") | H28: =IF($B28<>"","Fakhri Safrudin Sopandi","")
A29: =IF($B29<>"",ROW()-4,"") | H29: =IF($B29<>"","Fakhri Safrudin Sopandi","")
A30: =IF($B30<>"",ROW()-4,"") | H30: =IF($B30<>"","Fakhri Safrudin Sopandi","")
A31: =IF($B31<>"",ROW()-4,"") | H31: =IF($B31<>"","Fakhri Safrudin Sopandi","") | J31: Sabtu
A32: =IF($B32<>"",ROW()-4,"") | H32: =IF($B32<>"","Fakhri Safrudin Sopandi","")
A33: =IF($B33<>"",ROW()-4,"") | H33: =IF($B33<>"","Fakhri Safrudin Sopandi","")
A34: =IF($B34<>"",ROW()-4,"") | H34: =IF($B34<>"","Fakhri Safrudin Sopandi","")
A35: =IF($B35<>"",ROW()-4,"") | H35: =IF($B35<>"","Fakhri Safrudin Sopandi","")
A36: =IF($B36<>"",ROW()-4,"") | H36: =IF($B36<>"","Fakhri Safrudin Sopandi","")
A37: =IF($B37<>"",ROW()-4,"") | H37: =IF($B37<>"","Fakhri Safrudin Sopandi","")
A38: =IF($B38<>"",ROW()-4,"") | H38: =IF($B38<>"","Fakhri Safrudin Sopandi","")
A39: =IF($B39<>"",ROW()-4,"") | H39: =IF($B39<>"","Fakhri Safrudin Sopandi","")
A40: =IF($B40<>"",ROW()-4,"") | H40: =IF($B40<>"","Fakhri Safrudin Sopandi","")
...

Sheet Moh. Rizky Nugraha
A1: TWENTY SWIM - LEVEL SISWA & JADWAL LATIHAN (BANDUNG)
A2: Pelatih: Moh. Rizky Nugraha | D2: Terisi: | E2: =COUNTA($B$5:$B$54) | F2: siswa
A3: Isi kolom putih. Kolom berwarna = dropdown, tinggal pilih. No & Coach terisi otomatis.
A4: No | B4: Nama Siswa | C4: Program/Kelas | D4: Level Saat Ini | E4: Status | F4: Risiko | G4: Sosialisasi Keselamatan ke Ortu | H4: Coach | J4: JADWAL LATIHAN (Senin-Jumat 5 baris, Sabtu-Minggu 10 baris)
A5: =IF($B5<>"",ROW()-4,"") | B5: Fakhrie Azzam Ramdhani | D5: Intermediate I | E5: Standalone | H5: =IF($B5<>"","Moh. Rizky Nugraha","") | J5: Hari | K5: Jam | L5: Nama Siswa | M5: Lokasi (wilayah) | N5: Kolam
A6: =IF($B6<>"",ROW()-4,"") | B6: Nesya Maheswari | D6: Beginner I | E6: Standalone | H6: =IF($B6<>"","Moh. Rizky Nugraha","") | J6: Senin
A7: =IF($B7<>"",ROW()-4,"") | B7: Kamayel Zurio | C7: Baby Swim | D7: Baby Swim I | E7: PA | H7: =IF($B7<>"","Moh. Rizky Nugraha","")
A8: =IF($B8<>"",ROW()-4,"") | B8: Arvino Elghazi | D8: Beginner II | E8: Standalone | H8: =IF($B8<>"","Moh. Rizky Nugraha","")
A9: =IF($B9<>"",ROW()-4,"") | B9: Almira | D9: Beginner I | E9: Standalone | H9: =IF($B9<>"","Moh. Rizky Nugraha","")
A10: =IF($B10<>"",ROW()-4,"") | B10: Dhafir | D10: Beginner I | E10: Standalone | H10: =IF($B10<>"","Moh. Rizky Nugraha","")
A11: =IF($B11<>"",ROW()-4,"") | H11: =IF($B11<>"","Moh. Rizky Nugraha","") | J11: Selasa
A12: =IF($B12<>"",ROW()-4,"") | H12: =IF($B12<>"","Moh. Rizky Nugraha","")
A13: =IF($B13<>"",ROW()-4,"") | H13: =IF($B13<>"","Moh. Rizky Nugraha","")
A14: =IF($B14<>"",ROW()-4,"") | H14: =IF($B14<>"","Moh. Rizky Nugraha","")
A15: =IF($B15<>"",ROW()-4,"") | H15: =IF($B15<>"","Moh. Rizky Nugraha","")
A16: =IF($B16<>"",ROW()-4,"") | H16: =IF($B16<>"","Moh. Rizky Nugraha","") | J16: Rabu
A17: =IF($B17<>"",ROW()-4,"") | H17: =IF($B17<>"","Moh. Rizky Nugraha","")
A18: =IF($B18<>"",ROW()-4,"") | H18: =IF($B18<>"","Moh. Rizky Nugraha","")
A19: =IF($B19<>"",ROW()-4,"") | H19: =IF($B19<>"","Moh. Rizky Nugraha","")
A20: =IF($B20<>"",ROW()-4,"") | H20: =IF($B20<>"","Moh. Rizky Nugraha","")
A21: =IF($B21<>"",ROW()-4,"") | H21: =IF($B21<>"","Moh. Rizky Nugraha","") | J21: Kamis
A22: =IF($B22<>"",ROW()-4,"") | H22: =IF($B22<>"","Moh. Rizky Nugraha","")
A23: =IF($B23<>"",ROW()-4,"") | H23: =IF($B23<>"","Moh. Rizky Nugraha","")
A24: =IF($B24<>"",ROW()-4,"") | H24: =IF($B24<>"","Moh. Rizky Nugraha","")
A25: =IF($B25<>"",ROW()-4,"") | H25: =IF($B25<>"","Moh. Rizky Nugraha","")
A26: =IF($B26<>"",ROW()-4,"") | H26: =IF($B26<>"","Moh. Rizky Nugraha","") | J26: Jumat
A27: =IF($B27<>"",ROW()-4,"") | H27: =IF($B27<>"","Moh. Rizky Nugraha","")
A28: =IF($B28<>"",ROW()-4,"") | H28: =IF($B28<>"","Moh. Rizky Nugraha","")
A29: =IF($B29<>"",ROW()-4,"") | H29: =IF($B29<>"","Moh. Rizky Nugraha","")
A30: =IF($B30<>"",ROW()-4,"") | H30: =IF($B30<>"","Moh. Rizky Nugraha","")
A31: =IF($B31<>"",ROW()-4,"") | H31: =IF($B31<>"","Moh. Rizky Nugraha","") | J31: Sabtu
A32: =IF($B32<>"",ROW()-4,"") | H32: =IF($B32<>"","Moh. Rizky Nugraha","")
A33: =IF($B33<>"",ROW()-4,"") | H33: =IF($B33<>"","Moh. Rizky Nugraha","")
A34: =IF($B34<>"",ROW()-4,"") | H34: =IF($B34<>"","Moh. Rizky Nugraha","")
A35: =IF($B35<>"",ROW()-4,"") | H35: =IF($B35<>"","Moh. Rizky Nugraha","")
A36: =IF($B36<>"",ROW()-4,"") | H36: =IF($B36<>"","Moh. Rizky Nugraha","")
A37: =IF($B37<>"",ROW()-4,"") | H37: =IF($B37<>"","Moh. Rizky Nugraha","")
A38: =IF($B38<>"",ROW()-4,"") | H38: =IF($B38<>"","Moh. Rizky Nugraha","")
A39: =IF($B39<>"",ROW()-4,"") | H39: =IF($B39<>"","Moh. Rizky Nugraha","")
A40: =IF($B40<>"",ROW()-4,"") | H40: =IF($B40<>"","Moh. Rizky Nugraha","")
...

Sheet Muhammad Akbar Putra
A1: TWENTY SWIM - LEVEL SISWA & JADWAL LATIHAN (BANDUNG)
A2: Pelatih: Muhammad Akbar Putra | D2: Terisi: | E2: =COUNTA($B$5:$B$54) | F2: siswa
A3: Isi kolom putih. Kolom berwarna = dropdown, tinggal pilih. No & Coach terisi otomatis.
A4: No | B4: Nama Siswa | C4: Program/Kelas | D4: Level Saat Ini | E4: Status | F4: Risiko | G4: Sosialisasi Keselamatan ke Ortu | H4: Coach | J4: JADWAL LATIHAN (Senin-Jumat 5 baris, Sabtu-Minggu 10 baris)
A5: =IF($B5<>"",ROW()-4,"") | B5: Alaric Naufal Shafaraz | D5: Swim Team Prep | E5: Standalone | H5: =IF($B5<>"","Muhammad Akbar Putra","") | J5: Hari | K5: Jam | L5: Nama Siswa | M5: Lokasi (wilayah) | N5: Kolam
A6: =IF($B6<>"",ROW()-4,"") | B6: Dhirgam Evano H | D6: Beginner III | E6: Standalone | H6: =IF($B6<>"","Muhammad Akbar Putra","") | J6: Senin
A7: =IF($B7<>"",ROW()-4,"") | B7: Eliam Adley Eleazar | D7: Intermediate I | E7: Standalone | H7: =IF($B7<>"","Muhammad Akbar Putra","")
A8: =IF($B8<>"",ROW()-4,"") | B8: Adam Akbar Rizqiawan | D8: Intermediate I | E8: Standalone | H8: =IF($B8<>"","Muhammad Akbar Putra","")
A9: =IF($B9<>"",ROW()-4,"") | B9: Benedict Feifel Sugiarto | D9: Beginner III | E9: Standalone | H9: =IF($B9<>"","Muhammad Akbar Putra","")
A10: =IF($B10<>"",ROW()-4,"") | B10: Muhamad Hafiz Putra Pratama | D10: Beginner I | E10: Standalone | H10: =IF($B10<>"","Muhammad Akbar Putra","")
A11: =IF($B11<>"",ROW()-4,"") | B11: Deandra Arezky Ali | D11: Intermediate I | E11: Standalone | H11: =IF($B11<>"","Muhammad Akbar Putra","") | J11: Selasa
A12: =IF($B12<>"",ROW()-4,"") | B12: Fillio Azmi Hadyan | D12: Intermediate I | E12: Standalone | H12: =IF($B12<>"","Muhammad Akbar Putra","")
A13: =IF($B13<>"",ROW()-4,"") | B13: Keenan Athaya Kusumah | D13: Intermediate I | E13: Standalone | H13: =IF($B13<>"","Muhammad Akbar Putra","")
A14: =IF($B14<>"",ROW()-4,"") | B14: Atharizz Abbyan Kusumah | D14: Advanced II | E14: Standalone | H14: =IF($B14<>"","Muhammad Akbar Putra","")
